Workbook

Sheet 需求评估
A1: ID | B1: Function | C1: 需求 | D1: 业务备注 | E1: 种类 | F1: Focal | G1: 业务优先级 | H1: 排序 | I1: 开发难易度 | J1: IT类型 | K1: IT备注 | L1: MD | M1: 交付YR | N1: YR0 开发费用（折前） | O1: >Y0运营支持费（折前） | P1: >Y0运营平台费（折前） | Q1: YR0 开发费用 | R1: >Y0运营支持费 | S1: >Y0运营平台费 | T1: Task Name | U1: 交付YRQTR | V1: 起始日期 | W1: 结束日期 | X1: Status | Y1: Status Remark | Z1: 计划开始时间 | AA1: 计划结束时间 | AB1: Dev Pmt | AC1: Dev Pmt Date | AD1: Support Pmt | AE1: Support Pmt Date | AF1: Dev Pmt Timeline | AG1: Payment Remark | AH1: Dev Remainder
A2: 0 | B2: Billing | C2: 发票信息自动抽取解析 V1 | D2: 4/29+AC7+[@[@[Dev Pmt Date]] | E2: 发票 | F2: Baomei | G2: 中 | H2: 7 | I2: 中 | J2: 自动化 | K2: 第一期：部分平台已支持的语言OCR识别 | L2: 12 | M2: =LEFT(U2,4) -> 2526 | N2: =L2*360 -> 4320 | O2: =N2*0.2 -> 864 | P2: 100 | Q2: =N2*0.7 -> 3024 | R2: =SUM(O2) -> 864 | S2: =P2*0.5 -> 50 | T2: Automated Invoice Data Extraction and Parsing V1 | U2: =IF(OR(ISBLANK(Table1[[#This Row],[起始日期]]),Table1[[#This Row],[起始日期]]=""),RIGHT(YEAR(EDATE(Table1[[#This Row],[计划开始时间]],-3)),2) & RIGHT(YEAR(EDATE(Table1[[#This Row],[计划开始时间]],-3))+1,2) & " Q" & ROUNDUP(MONTH(EDATE(Table1[[#This Row],[计划开始时间]],-3))/3,0),RIGHT(YEAR(EDATE(Table1[[#This Row],[起始日期]],-3)),2) & RIGHT(YEAR(EDATE(Table1[[#This Row],[起始日期]],-3))+1,2) & " Q" & ROUNDUP(MONTH(EDATE(Table1[[#This Row],[起始日期]],-3))/3,0)) -> 2526 Q4 | X2: =IF( Table1[[#This Row],[ID]] = 0, "Cancelled", IF( Table1[[#This Row],[交付YRQTR]] = "TBD", "TBD", IF( ISBLANK(Table1[[#This Row],[计划开始时间]]), "Not Started", IF( AND( NOT(ISBLANK(Table1[[#This Row],[计划开始时间]])), Table1[[#This Row],[计划开始时间]] <= TODAY(), NOT(ISBLANK(Table1[[#This Row],[结束日期]])), Table1[[#This Row],[结束日期]] <= TODAY() ), "Completed", IF( OR( AND( Table1[[#This Row],[计划开始时间]] <= TODAY(), ISBLANK(Table1[[#This Row],[结束日期]]) ), AND( Table1[[#This Row],[计划开始时间]] <= TODAY(), Table1[[#This Row],[结束日期]] >= TODAY() ) ), "In Progress", "Not Started" ) ) ) )) -> Cancelled | Y2: 经前期调研发现难度较大，影响因素有文件格式、语言、位置不通等，需等OCR技术升级后再开发。 | Z2: 46082 | AA2: 46142 | AB2: 3024 | AC2: 45562 | AF2: FY2425 Q2 | AH2: =IF(Table1[[#This Row],[Dev Pmt]]="",Table1[[#This Row],[YR0 开发费用]]-0,Table1[[#This Row],[YR0 开发费用]]-Table1[[#This Row],[Dev Pmt]]) -> 0
A3: 0 | B3: Warehouse | C3: 关务账单审核 | D3: 1.真实性： 结合系统和HIC业务报表，判断账单上的业务是否实际发生。如果没有发生，系统将发出预警，需要人工再次确认。 -在ECC系统中查找账单上的BOL是否存在于系统内的ASN中对应的BOL- 如果当月数量不匹配，再看BOL是否存在于上个月（如果不存在同个月，看是否之前账单已charge过） 2.合理性： 结合系统和HIC业务报表，判断账单上发生的业务是否必要。如果判断为非必要，系统也将发出预警，需要人工干预。（Lingling 后续输出具体逻辑规则和明确的场景去判断）-放在第二个阶段，需要AI大模型 *第一次的账单，SSC 提供前2-3个月的历史账单给到AMS | E3: 关务 | F3: Fangmin | G3: 中 | H3: 20 | I3: 低 | J3: 自动化 | L3: 15 | M3: =LEFT(U3,4) -> 2627 | N3: =L3*330 -> 4950 | O3: =N3*0.2 -> 990 | P3: 100 | Q3: =N3*0.7 -> 3465 | R3: =SUM(O3) -> 990 | S3: =P3*0.5 -> 50 | T3: Customs Bill Auditing | U3: 2627 Q1 | X3: =IF( Table1[[#This Row],[ID]] = 0, "Cancelled", IF( Table1[[#This Row],[交付YRQTR]] = "TBD", "TBD", IF( ISBLANK(Table1[[#This Row],[计划开始时间]]), "Not Started", IF( AND( NOT(ISBLANK(Table1[[#This Row],[计划开始时间]])), Table1[[#This Row],[计划开始时间]] <= TODAY(), NOT(ISBLANK(Table1[[#This Row],[结束日期]])), Table1[[#This Row],[结束日期]] <= TODAY() ), "Completed", IF( OR( AND( Table1[[#This Row],[计划开始时间]] <= TODAY(), ISBLANK(Table1[[#This Row],[结束日期]]) ), AND( Table1[[#This Row],[计划开始时间]] <= TODAY(), Table1[[#This Row],[结束日期]] >= TODAY() ) ), "In Progress", "Not Started" ) ) ) )) -> Cancelled | AB3: =Table1[[#This Row],[YR0 开发费用]] -> 3465 | AC3: 45776 | AF3: FY2526 Q1 | AH3: =IF(Table1[[#This Row],[Dev Pmt]]="",Table1[[#This Row],[YR0 开发费用]]-0,Table1[[#This Row],[YR0 开发费用]]-Table1[[#This Row],[Dev Pmt]]) -> 0
A4: 0 | B4: Billing | C4: 发票信息自动抽取解析 V2 | D4: 解决发票以及清关文件等PDF文件格式不统一、20多语言混合等问题，实现发票和文件信息自动抽取解析: 1.下载文件，转存文件 2. 解压缩文件(if any) 3. 上传文件，解析 4. 提取信息存储 5. 一次处理100多个文件 | E4: 发票 | F4: Baomei | G4: 中 | H4: 18 | I4: 中 | J4: 自动化 | K4: 第二期：升级 | L4: 12 | M4: =LEFT(U4,4) -> 2526 | N4: =L4*330 -> 3960 | O4: =N4*0.2 -> 792 | P4: 100 | Q4: =N4 -> 3960 | R4: =SUM(O4) -> 792 | S4: =P4*0.5 -> 50 | T4: Automated Invoice Data Extraction and Parsing V2 | U4: 2526 Q4 | X4: =IF( Table1[[#This Row],[ID]] = 0, "Cancelled", IF( Table1[[#This Row],[交付YRQTR]] = "TBD", "TBD", IF( ISBLANK(Table1[[#This Row],[计划开始时间]]), "Not Started", IF( AND( NOT(ISBLANK(Table1[[#This Row],[计划开始时间]])), Table1[[#This Row],[计划开始时间]] <= TODAY(), NOT(ISBLANK(Table1[[#This Row],[结束日期]])), Table1[[#This Row],[结束日期]] <= TODAY() ), "Completed", IF( OR( AND( Table1[[#This Row],[计划开始时间]] <= TODAY(), ISBLANK(Table1[[#This Row],[结束日期]]) ), AND( Table1[[#This Row],[计划开始时间]] <= TODAY(), Table1[[#This Row],[结束日期]] >= TODAY() ) ), "In Progress", "Not Started" ) ) ) )) -> Cancelled | AF4: FY2526 Q3 | AH4: =IF(Table1[[#This Row],[Dev Pmt]]="",Table1[[#This Row],[YR0 开发费用]]-0,Table1[[#This Row],[YR0 开发费用]]-Table1[[#This Row],[Dev Pmt]]) -> 3960
A5: 0 | B5: Warehouse | C5: 报关信息汇总 | D5: 提供报关信息上传出口以便于供应商上传文件，抓取料号关键信息，最后可通过输入PN（Part number) 或其他关键信息查询到累积的数据 场景1：同个PN会有不同的供应商 场景2：同个PN会有不同的HS code 场景3：同个PN会有不同的申报要素 场景4：同个PN会有不同的原产国 场景5：同个PN会有不同的品名 （不看入库日期， 和数量） PN第一次入库HIC只会记录第一次PN来料主数据，目的是掌握同个PN每次入库五个场景当中所有的关键信息。 项目开始取决于HIC报关行能否提供PN每次入库信息，需要与报关行确定来源接收方式） 输出方式：以PN形式记录 | E5: 关务 | F5: Fangmin | G5: 中 | H5: 13 | I5: 中 | J5: 平台 | L5: 20 | M5: =LEFT(U5,4) -> 2526 | N5: =L5*330 -> 6600 | O5: =N5*0.2 -> 1320 | P5: 100 | Q5: =N5 -> 6600 | R5: =SUM(O5) -> 1320 | S5: =P5*0.5 -> 50 | T5: Customs Information Summary | U5: 2526 Q3 | X5: =IF( Table1[[#This Row],[ID]] = 0, "Cancelled", IF( Table1[[#This Row],[交付YRQTR]] = "TBD", "TBD", IF( ISBLANK(Table1[[#This Row],[计划开始时间]]), "Not Started", IF( AND( NOT(ISBLANK(Table1[[#This Row],[计划开始时间]])), Table1[[#This Row],[计划开始时间]] <= TODAY(), NOT(ISBLANK(Table1[[#This Row],[结束日期]])), Table1[[#This Row],[结束日期]] <= TODAY() ), "Completed", IF( OR( AND( Table1[[#This Row],[计划开始时间]] <= TODAY(), ISBLANK(Table1[[#This Row],[结束日期]]) ), AND( Table1[[#This Row],[计划开始时间]] <= TODAY(), Table1[[#This Row],[结束日期]] >= TODAY() ) ), "In Progress", "Not Started" ) ) ) )) -> Cancelled | AF5: FY2526 Q3 | AH5: =IF(Table1[[#This Row],[Dev Pmt]]="",Table1[[#This Row],[YR0 开发费用]]-0,Table1[[#This Row],[YR0 开发费用]]-Table1[[#This Row],[Dev Pmt]]) -> 6600
A6: 0 | B6: Billing | C6: 自动各国假期提醒 | D6: 十几个各国每年假期时间信息/各供应商/各部门假期时间, 统计汇总提醒 | E6: 发票 | F6: Baomei | G6: 低 | H6: 27 | I6: 中 | J6: 自动化 | L6: 15 | M6: =LEFT(U6,4) -> 2627 | N6: =L6*330 -> 4950 | O6: =N6*0.2 -> 990 | P6: 100 | Q6: =N6 -> 4950 | R6: =SUM(O6) -> 990 | S6: =P6*0.5 -> 50 | T6: Automated National Holiday Alerts | U6: 2627 Q1 | X6: =IF( Table1[[#This Row],[ID]] = 0, "Cancelled", IF( Table1[[#This Row],[交付YRQTR]] = "TBD", "TBD", IF( ISBLANK(Table1[[#This Row],[计划开始时间]]), "Not Started", IF( AND( NOT(ISBLANK(Table1[[#This Row],[计划开始时间]])), Table1[[#This Row],[计划开始时间]] <= TODAY(), NOT(ISBLANK(Table1[[#This Row],[结束日期]])), Table1[[#This Row],[结束日期]] <= TODAY() ), "Completed", IF( OR( AND( Table1[[#This Row],[计划开始时间]] <= TODAY(), ISBLANK(Table1[[#This Row],[结束日期]]) ), AND( Table1[[#This Row],[计划开始时间]] <= TODAY(), Table1[[#This Row],[结束日期]] >= TODAY() ) ), "In Progress", "Not Started" ) ) ) )) -> Cancelled | AF6: FY2627 Q1 | AH6: =IF(Table1[[#This Row],[Dev Pmt]]="",Table1[[#This Row],[YR0 开发费用]]-0,Table1[[#This Row],[YR0 开发费用]]-Table1[[#This Row],[Dev Pmt]]) -> 4950
A7: 0 | B7: Billing | C7: 料号估算计费重量 | D7: 1. PN 数据（长宽高） 2. 账单数据 （计费重量） 3. 估算PN，发货AWB的计费重量 | E7: 发票 | F7: Baomei | G7: 低 | H7: 28 | I7: 中 | J7: 自动化 | L7: 20 | M7: =LEFT(U7,4) -> 2627 | N7: =L7*330 -> 6600 | O7: =N7*0.2 -> 1320 | P7: 100 | Q7: =N7 -> 6600 | R7: =SUM(O7) -> 1320 | S7: =P7*0.5 -> 50 | T7: Part Number Billing Weight Estimation | U7: 2627 Q1 | X7: =IF( Table1[[#This Row],[ID]] = 0, "Cancelled", IF( Table1[[#This Row],[交付YRQTR]] = "TBD", "TBD", IF( ISBLANK(Table1[[#This Row],[计划开始时间]]), "Not Started", IF( AND( NOT(ISBLANK(Table1[[#This Row],[计划开始时间]])), Table1[[#This Row],[计划开始时间]] <= TODAY(), NOT(ISBLANK(Table1[[#This Row],[结束日期]])), Table1[[#This Row],[结束日期]] <= TODAY() ), "Completed", IF( OR( AND( Table1[[#This Row],[计划开始时间]] <= TODAY(), ISBLANK(Table1[[#This Row],[结束日期]]) ), AND( Table1[[#This Row],[计划开始时间]] <= TODAY(), Table1[[#This Row],[结束日期]] >= TODAY() ) ), "In Progress", "Not Started" ) ) ) )) -> Cancelled | AF7: FY2627 Q1 | AH7: =IF(Table1[[#This Row],[Dev Pmt]]="",Table1[[#This Row],[YR0 开发费用]]-0,Table1[[#This Row],[YR0 开发费用]]-Table1[[#This Row],[Dev Pmt]]) -> 6600
A8: 0 | B8: Warehouse | C8: 运输实时线上监控平台 | D8: JYD和SF可以连GPS系统，HIC连FTP查询货物状态（HIC可以利用LT逻辑估算） | E8: 运输 | F8: Yuchang | G8: 低 | H8: 29 | I8: 中 | J8: 平台 | K8: 1、获取HIC ftp的数据，关于物流信息可能涉及到第三方物流网站 可以考虑同第6条一起开发 2、连JYD\SF的系统获取运输状态，其中JYD可以提供接口，SF从官网爬取信息 | L8: 30 | M8: =LEFT(U8,4) -> 2627 | N8: =L8*330 -> 9900 | O8: =N8*0.2 -> 1980 | P8: 100 | Q8: =N8 -> 9900 | R8: =SUM(O8) -> 1980 | S8: =P8*0.5 -> 50 | T8: Real-Time Transport Monitoring Platform | U8: 2627 Q1 | X8: =IF( Table1[[#This Row],[ID]] = 0, "Cancelled", IF( Table1[[#This Row],[交付YRQTR]] = "TBD", "TBD", IF( ISBLANK(Table1[[#This Row],[计划开始时间]]), "Not Started", IF( AND( NOT(ISBLANK(Table1[[#This Row],[计划开始时间]])), Table1[[#This Row],[计划开始时间]] <= TODAY(), NOT(ISBLANK(Table1[[#This Row],[结束日期]])), Table1[[#This Row],[结束日期]] <= TODAY() ), "Completed", IF( OR( AND( Table1[[#This Row],[计划开始时间]] <= TODAY(), ISBLANK(Table1[[#This Row],[结束日期]]) ), AND( Table1[[#This Row],[计划开始时间]] <= TODAY(), Table1[[#This Row],[结束日期]] >= TODAY() ) ), "In Progress", "Not Started" ) ) ) )) -> Cancelled | AF8: FY2627 Q1 | AH8: =IF(Table1[[#This Row],[Dev Pmt]]="",Table1[[#This Row],[YR0 开发费用]]-0,Table1[[#This Row],[YR0 开发费用]]-Table1[[#This Row],[Dev Pmt]]) -> 9900
A9: 0 | B9: Warehouse | C9: 电池图片智能识别 | D9: ‘-自动识别备件图片中的LOGO或关键信息,与资料上的关键信息比对,检查是否一致。 -自动识别备件实物图片中的外观,与资料中的备件外观进行比对,检查是否一模一样(针对电池)。 -自动识别备件外观,并判断属于哪类备件(用于关务)。 | E9: 电池 | F9: Fangmin | G9: 低 | I9: 高 | J9: 平台 | K9: 实现困难，成本过高 | M9: =LEFT(U9,4) -> TBD | N9: =L9*360 -> 0 | O9: =N9*0.2 -> 0 | P9: 100 | Q9: =N9*0.7 -> 0 | R9: =SUM(O9) -> 0 | S9: 0 | T9: Intelligent Battery Image Recognition | U9: TBD | X9: =IF( Table1[[#This Row],[ID]] = 0, "Cancelled", IF( Table1[[#This Row],[交付YRQTR]] = "TBD", "TBD", IF( ISBLANK(Table1[[#This Row],[计划开始时间]]), "Not Started", IF( AND( NOT(ISBLANK(Table1[[#This Row],[计划开始时间]])), Table1[[#This Row],[计划开始时间]] <= TODAY(), NOT(ISBLANK(Table1[[#This Row],[结束日期]])), Table1[[#This Row],[结束日期]] <= TODAY() ), "Completed", IF( OR( AND( Table1[[#This Row],[计划开始时间]] <= TODAY(), ISBLANK(Table1[[#This Row],[结束日期]]) ), AND( Table1[[#This Row],[计划开始时间]] <= TODAY(), Table1[[#This Row],[结束日期]] >= TODAY() ) ), "In Progress", "Not Started" ) ) ) )) -> Cancelled | AH9: =IF(Table1[[#This Row],[Dev Pmt]]="",Table1[[#This Row],[YR0 开发费用]]-0,Table1[[#This Row],[YR0 开发费用]]-Table1[[#This Row],[Dev Pmt]]) -> 0
A10: 0 | B10: Billing | C10: 账单报错解决方案 | D10: AI 大模型解决方案：生成报错文件并自动发送 从BPS 报错信息开始错误分类，标记，邮件draft到邮件生成 1. 报错信息分两层：Step1. 根据BPS error code然后做一个初步分类，指出发生的原因，确定核对的方向； 2. 根据初步的分类，找到深层原因，比如rate不一致，具体原因是哪一个信息导致的不一致，如country不一致，还是SL不一致等等。。。（这一步可能会涉及到BPS深层配置信息，需要和BPS/Hedy确认是否需要进行到这一步，是否会存在risk） 方案：billing owner自己下载error report上传到指定的sharepoint folder，然后自动运行后返回一个预期结果（邮件返回或者文件夹返回） | E10: 发票 | F10: Baomei | G10: 高 | I10: 高 | J10: 自动化 | K10: 业务背景有待讨论，预估时间不准确（20+20） | L10: 50 | M10: =LEFT(U10,4) -> 2526 | N10: =L10*330 -> 16500 | O10: =N10*0.2 -> 3300 | P10: 100 | Q10: =N10 -> 16500 | R10: =SUM(O10) -> 3300 | S10: =P10*0.5 -> 50 | T10: Billing Error Resolution Solutions | U10: =IF(OR(ISBLANK(Table1[[#This Row],[起始日期]]),Table1[[#This Row],[起始日期]]=""),RIGHT(YEAR(EDATE(Table1[[#This Row],[计划开始时间]],-3)),2) & RIGHT(YEAR(EDATE(Table1[[#This Row],[计划开始时间]],-3))+1,2) & " Q" & ROUNDUP(MONTH(EDATE(Table1[[#This Row],[计划开始时间]],-3))/3,0),RIGHT(YEAR(EDATE(Table1[[#This Row],[起始日期]],-3)),2) & RIGHT(YEAR(EDATE(Table1[[#This Row],[起始日期]],-3))+1,2) & " Q" & ROUNDUP(MONTH(EDATE(Table1[[#This Row],[起始日期]],-3))/3,0)) -> 2526 Q4 | X10: =IF( Table1[[#This Row],[ID]] = 0, "Cancelled", IF( Table1[[#This Row],[交付YRQTR]] = "TBD", "TBD", IF( ISBLANK(Table1[[#This Row],[计划开始时间]]), "Not Started", IF( AND( NOT(ISBLANK(Table1[[#This Row],[计划开始时间]])), Table1[[#This Row],[计划开始时间]] <= TODAY(), NOT(ISBLANK(Table1[[#This Row],[结束日期]])), Table1[[#This Row],[结束日期]] <= TODAY() ), "Completed", IF( OR( AND( Table1[[#This Row],[计划开始时间]] <= TODAY(), ISBLANK(Table1[[#This Row],[结束日期]]) ), AND( Table1[[#This Row],[计划开始时间]] <= TODAY(), Table1[[#This Row],[结束日期]] >= TODAY() ) ), "In Progress", "Not Started" ) ) ) )) -> Cancelled | Z10: 46082 | AA10: 46142 | AF10: FY2526 Q3 | AH10: =IF(Table1[[#This Row],[Dev Pmt]]="",Table1[[#This Row],[YR0 开发费用]]-0,Table1[[#This Row],[YR0 开发费用]]-Table1[[#This Row],[Dev Pmt]]) -> 16500
A11: 0 | B11: Warehouse | C11: Rebalance 自动提取open订单 | D11: 参考附件文档 | E11: SAP | F11: Daniel | G11: 中 | H11: 14 | I11: 低 | J11: 自动化 | L11: 5 | M11: =LEFT(U11,4) -> 2425 | N11: 1800 | O11: 360 | P11: 100 | Q11: =N11*0.7 -> 1260 | R11: =SUM(O11) -> 360 | S11: =P11*0.5 -> 50 | T11: Rebalance Open Order Auto-Extraction | U11: 2425 Q3 | X11: =IF( Table1[[#This Row],[ID]] = 0, "Cancelled", IF( Table1[[#This Row],[交付YRQTR]] = "TBD", "TBD", IF( ISBLANK(Table1[[#This Row],[计划开始时间]]), "Not Started", IF( AND( NOT(ISBLANK(Table1[[#This Row],[计划开始时间]])), Table1[[#This Row],[计划开始时间]] <= TODAY(), NOT(ISBLANK(Table1[[#This Row],[结束日期]])), Table1[[#This Row],[结束日期]] <= TODAY() ), "Completed", IF( OR( AND( Table1[[#This Row],[计划开始时间]] <= TODAY(), ISBLANK(Table1[[#This Row],[结束日期]]) ), AND( Table1[[#This Row],[计划开始时间]] <= TODAY(), Table1[[#This Row],[结束日期]] >= TODAY() ) ), "In Progress", "Not Started" ) ) ) )) -> Cancelled | AB11: =1260-1260 -> 0 | AC11: 45562 | AG11: Paid dev on 24/9/27, deducted on 25/1/22 | AH11: =IF(Table1[[#This Row],[Dev Pmt]]="",Table1[[#This Row],[YR0 开发费用]]-0,Table1[[#This Row],[YR0 开发费用]]-Table1[[#This Row],[Dev Pmt]]) -> 1260
A12: 0 | B12: Warehouse | C12: Rebalance ASN生成自动提醒 | D12: 参考附件文档 | E12: Rebalance | F12: Daniel | G12: 中 | H12: 17 | I12: 低 | J12: 自动化 | L12: 5 | M12: =LEFT(U12,4) -> 2526 | N12: 1800 | O12: 360 | P12: 100 | Q12: =N12*0.7 -> 1260 | R12: =SUM(O12) -> 360 | S12: =P12*0.5 -> 50 | T12: Rebalance ASN Auto-Reminders | U12: 2526 Q2 | X12: =IF( Table1[[#This Row],[ID]] = 0, "Cancelled", IF( Table1[[#This Row],[交付YRQTR]] = "TBD", "TBD", IF( ISBLANK(Table1[[#This Row],[计划开始时间]]), "Not Started", IF( AND( NOT(ISBLANK(Table1[[#This Row],[计划开始时间]])), Table1[[#This Row],[计划开始时间]] <= TODAY(), NOT(ISBLANK(Table1[[#This Row],[结束日期]])), Table1[[#This Row],[结束日期]] <= TODAY() ), "Completed", IF( OR( AND( Table1[[#This Row],[计划开始时间]] <= TODAY(), ISBLANK(Table1[[#This Row],[结束日期]]) ), AND( Table1[[#This Row],[计划开始时间]] <= TODAY(), Table1[[#This Row],[结束日期]] >= TODAY() ) ), "In Progress", "Not Started" ) ) ) )) -> Cancelled | AH12: =IF(Table1[[#This Row],[Dev Pmt]]="",Table1[[#This Row],[YR0 开发费用]]-0,Table1[[#This Row],[YR0 开发费用]]-Table1[[#This Row],[Dev Pmt]]) -> 1260
A13: 0 | B13: Billing | C13: 自动计算未开账单 | D13: 物流操作产生的费用，未开账单的评估测算。自生成账单: 1. 仓储数据/发货数据集成 2. 根据历史发货数据，账单数据分析cost/pc, cost/kg 3. 预估还未收到的账单cost | E13: 发票 | F13: Baomei | G13: 低 | H13: 16 | I13: 中 | J13: 自动化 | L13: 20 | M13: =LEFT(U13,4) -> 2526 | N13: =L13*330 -> 6600 | O13: =N13*0.2 -> 1320 | P13: 100 | Q13: =N13*0.7 -> 4620 | R13: =SUM(O13) -> 1320 | S13: =P13*0.5 -> 50 | T13: Automated Unbilled Amount Calculation | U13: 2526 Q4 | X13: =IF( Table1[[#This Row],[ID]] = 0, "Cancelled", IF( Table1[[#This Row],[交付YRQTR]] = "TBD", "TBD", IF( ISBLANK(Table1[[#This Row],[计划开始时间]]), "Not Started", IF( AND( NOT(ISBLANK(Table1[[#This Row],[计划开始时间]])), Table1[[#This Row],[计划开始时间]] <= TODAY(), NOT(ISBLANK(Table1[[#This Row],[结束日期]])), Table1[[#This Row],[结束日期]] <= TODAY() ), "Completed", IF( OR( AND( Table1[[#This Row],[计划开始时间]] <= TODAY(), ISBLANK(Table1[[#This Row],[结束日期]]) ), AND( Table1[[#This Row],[计划开始时间]] <= TODAY(), Table1[[#This Row],[结束日期]] >= TODAY() ) ), "In Progress", "Not Started" ) ) ) )) -> Cancelled | AC13: =IF(OR(Table1[[#This Row],[Dev Pmt]]=0,Table1[[#This Row],[Dev Pmt]]=""),"","2024/9/27") | AF13: FY2526 Q3 | AH13: =IF(Table1[[#This Row],[Dev Pmt]]="",Table1[[#This Row],[YR0 开发费用]]-0,Table1[[#This Row],[YR0 开发费用]]-Table1[[#This Row],[Dev Pmt]]) -> 4620
A14: 0 | B14: Billing | C14: 不同格式的报价统一化 | D14: 1. 供应商报价文件 2. 根据模板转换文件数据 | E14: 发票 | F14: Baomei | G14: 中 | H14: 24 | I14: 低 | J14: 自动化 | K14: 按供应商的不同文件格式*1 数据获取待确定 | L14: 20 | M14: =LEFT(U14,4) -> 2526 | N14: =L14*330 -> 6600 | O14: =N14*0.2 -> 1320 | P14: 100 | Q14: =N14*0.7 -> 4620 | R14: =SUM(O14) -> 1320 | S14: =P14*0.5 -> 50 | T14: Standardized Rate Quote Formatting | U14: 2526 Q4 | X14: =IF( Table1[[#This Row],[ID]] = 0, "Cancelled", IF( Table1[[#This Row],[交付YRQTR]] = "TBD", "TBD", IF( ISBLANK(Table1[[#This Row],[计划开始时间]]), "Not Started", IF( AND( NOT(ISBLANK(Table1[[#This Row],[计划开始时间]])), Table1[[#This Row],[计划开始时间]] <= TODAY(), NOT(ISBLANK(Table1[[#This Row],[结束日期]])), Table1[[#This Row],[结束日期]] <= TODAY() ), "Completed", IF( OR( AND( Table1[[#This Row],[计划开始时间]] <= TODAY(), ISBLANK(Table1[[#This Row],[结束日期]]) ), AND( Table1[[#This Row],[计划开始时间]] <= TODAY(), Table1[[#This Row],[结束日期]] >= TODAY() ) ), "In Progress", "Not Started" ) ) ) )) -> Cancelled | AC14: =IF(OR(Table1[[#This Row],[Dev Pmt]]=0,Table1[[#This Row],[Dev Pmt]]=""),"","2024/9/27") | AF14: FY2526 Q3 | AH14: =IF(Table1[[#This Row],[Dev Pmt]]="",Table1[[#This Row],[YR0 开发费用]]-0,Table1[[#This Row],[YR0 开发费用]]-Table1[[#This Row],[Dev Pmt]]) -> 4620
A15: 0 | B15: Data | C15: 干预模型 V2 | D15: 增加前端页面、增删查改功能、ticket单据信息与数据库信息及前端页面展示信息同步功能 | E15: 物流 | F15: Kevin | G15: 中 | I15: 中 | J15: 平台 | K15: 增加前端页面、增删查改功能、ticket单据信息与数据库信息及前端页面展示信息同步功能 | L15: 40 | M15: =LEFT(U15,4) -> 2526 | N15: =L15*330 -> 13200 | O15: =L15*330*0.2 -> 2640 | P15: =100 -> 100 | Q15: =N15*0.7 -> 9240 | R15: =SUM(O15) -> 2640 | S15: =P15*0.5 -> 50 | T15: Live Interception Platform V2 | U15: =IF(OR(ISBLANK(Table1[[#This Row],[起始日期]]),Table1[[#This Row],[起始日期]]=""),RIGHT(YEAR(EDATE(Table1[[#This Row],[计划开始时间]],-3)),2) & RIGHT(YEAR(EDATE(Table1[[#This Row],[计划开始时间]],-3))+1,2) & " Q" & ROUNDUP(MONTH(EDATE(Table1[[#This Row],[计划开始时间]],-3))/3,0),RIGHT(YEAR(EDATE(Table1[[#This Row],[起始日期]],-3)),2) & RIGHT(YEAR(EDATE(Table1[[#This Row],[起始日期]],-3))+1,2) & " Q" & ROUNDUP(MONTH(EDATE(Table1[[#This Row],[起始日期]],-3))/3,0)) -> 2526 Q3 | V15: 45992 | X15: =IF( Table1[[#This Row],[ID]] = 0, "Cancelled", IF( Table1[[#This Row],[交付YRQTR]] = "TBD", "TBD", IF( ISBLANK(Table1[[#This Row],[计划开始时间]]), "Not Started", IF( AND( NOT(ISBLANK(Table1[[#This Row],[计划开始时间]])), Table1[[#This Row],[计划开始时间]] <= TODAY(), NOT(ISBLANK(Table1[[#This Row],[结束日期]])), Table1[[#This Row],[结束日期]] <= TODAY() ), "Completed", IF( OR( AND( Table1[[#This Row],[计划开始时间]] <= TODAY(), ISBLANK(Table1[[#This Row],[结束日期]]) ), AND( Table1[[#This Row],[计划开始时间]] <= TODAY(), Table1[[#This Row],[结束日期]] >= TODAY() ) ), "In Progress", "Not Started" ) ) ) )) -> Cancelled | Z15: 46113 | AA15: 46203 | AB15: =Table1[[#This Row],[YR0 开发费用]] -> 9240 | AC15: 45776 | AF15: FY2526 Q1 | AH15: =IF(Table1[[#This Row],[Dev Pmt]]="",Table1[[#This Row],[YR0 开发费用]]-0,Table1[[#This Row],[YR0 开发费用]]-Table1[[#This Row],[Dev Pmt]]) -> 0
A16: 0 | B16: BI | C16: Smart Delivery UI Platform V1 | D16: 1.智能交付Web用户界面（查询/仪表盘/设置等） 2.可配置的ETL接口（API/Kafka/ODBC/JDBC/手动上传等） 3.可配置的ETL处理流程 4.基于Python的可配置机器学习算法接口（3.9或以上版本，可升级） 5.实时拦截干预处理（通知相应的对接人） 6.端到端加速接口（API） 注解： 1.开发一个替代Power BI的平台，功能包括数据查询、数据展示和数据交互。 2.接收并处理来自外部的各种不同格式的客户数据。 3.转换外部的数据去调整算法 4.提供机器学习算法，并能够升级和优化现有算法。 5.实时干预系统：基于算法预测的预计到达时间（ETA）来通知用户和相关负责人，平台设有按钮可以直接通知相关人员 6.E2E加急订单API（联系到客户，如单号通过API同步给客户） | E16: 物流 | F16: Kevin | G16: 高 | H16: 15 | I16: 高 | J16: 平台 | K16: 第一期：powerBI平台主仪表板迁移（数据查询、展示、交互）、实时干预、E2E加急订单API（联系到客户，如单号通过API同步给客户）、机器学习算法接口 | L16: 60 | M16: =LEFT(U16,4) -> 2526 | N16: =L16*330 -> 19800 | O16: =N16*0.2 -> 3960 | P16: 100 | Q16: =N16 -> 19800 | R16: =SUM(O16) -> 3960 | S16: =P16*0.5 -> 50 | T16: Smart Delivery UI Platform V1 | U16: 2526 Q4 | X16: =IF( Table1[[#This Row],[ID]] = 0, "Cancelled", IF( Table1[[#This Row],[交付YRQTR]] = "TBD", "TBD", IF( ISBLANK(Table1[[#This Row],[计划开始时间]]), "Not Started", IF( AND( NOT(ISBLANK(Table1[[#This Row],[计划开始时间]])), Table1[[#This Row],[计划开始时间]] <= TODAY(), NOT(ISBLANK(Table1[[#This Row],[结束日期]])), Table1[[#This Row],[结束日期]] <= TODAY() ), "Completed", IF( OR( AND( Table1[[#This Row],[计划开始时间]] <= TODAY(), ISBLANK(Table1[[#This Row],[结束日期]]) ), AND( Table1[[#This Row],[计划开始时间]] <= TODAY(), Table1[[#This Row],[结束日期]] >= TODAY() ) ), "In Progress", "Not Started" ) ) ) )) -> Cancelled | AF16: FY2526 Q3 | AH16: =IF(Table1[[#This Row],[Dev Pmt]]="",Table1[[#This Row],[YR0 开发费用]]-0,Table1[[#This Row],[YR0 开发费用]]-Table1[[#This Row],[Dev Pmt]]) -> 19800
A17: 0 | B17: BI | C17: Smart Delivery UI Platform V2 | D17: 1.智能交付Web用户界面（查询/仪表盘/设置等） 2.可配置的ETL接口（API/Kafka/ODBC/JDBC/手动上传等） 3.可配置的ETL处理流程 4.基于Python的可配置机器学习算法接口（3.9或以上版本，可升级） 5.实时拦截干预处理（通知相应的对接人） 6.端到端加速接口（API） 注解： 1.开发一个替代Power BI的平台，功能包括数据查询、数据展示和数据交互。 2.接收并处理来自外部的各种不同格式的客户数据。 3.转换外部的数据去调整算法 4.提供机器学习算法，并能够升级和优化现有算法。 5.实时干预系统：基于算法预测的预计到达时间（ETA）来通知用户和相关负责人，平台设有按钮可以直接通知相关人员 6.E2E加急订单API（联系到客户，如单号通过API同步给客户） | E17: 物流 | F17: Kevin | G17: 高 | H17: 26 | I17: 高 | J17: 平台 | K17: 第二期：数据集成（API/Kafka/ODBC/JDBC/手动上传等）、陆续迁移其他PowerBI报表、机器学习算法优化 | L17: 60 | M17: =LEFT(U17,4) -> 2627 | N17: =L17*330 -> 19800 | O17: =N17*0.2 -> 3960 | P17: 100 | Q17: =N17 -> 19800 | R17: =SUM(O17) -> 3960 | S17: =P17*0.5 -> 50 | T17: Smart Delivery UI Platform V2 | U17: 2627 Q2 | X17: =IF( Table1[[#This Row],[ID]] = 0, "Cancelled", IF( Table1[[#This Row],[交付YRQTR]] = "TBD", "TBD", IF( ISBLANK(Table1[[#This Row],[计划开始时间]]), "Not Started", IF( AND( NOT(ISBLANK(Table1[[#This Row],[计划开始时间]])), Table1[[#This Row],[计划开始时间]] <= TODAY(), NOT(ISBLANK(Table1[[#This Row],[结束日期]])), Table1[[#This Row],[结束日期]] <= TODAY() ), "Completed", IF( OR( AND( Table1[[#This Row],[计划开始时间]] <= TODAY(), ISBLANK(Table1[[#This Row],[结束日期]]) ), AND( Table1[[#This Row],[计划开始时间]] <= TODAY(), Table1[[#This Row],[结束日期]] >= TODAY() ) ), "In Progress", "Not Started" ) ) ) )) -> Cancelled | AF17: FY2627 Q1 | AH17: =IF(Table1[[#This Row],[Dev Pmt]]="",Table1[[#This Row],[YR0 开发费用]]-0,Table1[[#This Row],[YR0 开发费用]]-Table1[[#This Row],[Dev Pmt]]) -> 19800
A18: 0 | B18: Compliance | C18: Smart GTC Management V1 | D18: 开展AI信息识别和抓取报关单信息，并比对原有数据库信息，并发出不一致预警。 1. HS数据AI智能分类： -.利用数据库内的料号和料号描述信息 -通过自有算法、深度机器学习或外部AI机器学习技术 -对料号进行HS code预分类 -物料号+HS code表 | E18: 安规 | F18: Bob | G18: 高 | H18: 17 | I18: 高 | J18: 平台 | K18: 依据海关总署归类规则筛选电子类/电脑类、机器学习模拟分类结果 需要调研在探讨能不能做 | L18: 20 | M18: =LEFT(U18,4) -> 2526 | N18: =L18*330 -> 6600 | O18: =N18*0.2 -> 1320 | P18: 100 | Q18: =N18 -> 6600 | R18: =SUM(O18) -> 1320 | S18: =P18*0.5 -> 50 | T18: Smart GTC Management V1 | U18: 2526 Q3 | X18: =IF( Table1[[#This Row],[ID]] = 0, "Cancelled", IF( Table1[[#This Row],[交付YRQTR]] = "TBD", "TBD", IF( ISBLANK(Table1[[#This Row],[计划开始时间]]), "Not Started", IF( AND( NOT(ISBLANK(Table1[[#This Row],[计划开始时间]])), Table1[[#This Row],[计划开始时间]] <= TODAY(), NOT(ISBLANK(Table1[[#This Row],[结束日期]])), Table1[[#This Row],[结束日期]] <= TODAY() ), "Completed", IF( OR( AND( Table1[[#This Row],[计划开始时间]] <= TODAY(), ISBLANK(Table1[[#This Row],[结束日期]]) ), AND( Table1[[#This Row],[计划开始时间]] <= TODAY(), Table1[[#This Row],[结束日期]] >= TODAY() ) ), "In Progress", "Not Started" ) ) ) )) -> Cancelled | AF18: FY2526 Q3 | AH18: =IF(Table1[[#This Row],[Dev Pmt]]="",Table1[[#This Row],[YR0 开发费用]]-0,Table1[[#This Row],[YR0 开发费用]]-Table1[[#This Row],[Dev Pmt]]) -> 6600
A19: 0 | B19: Compliance | C19: Smart GTC Management V2 | D19: 开展AI信息识别和抓取报关单信息，并比对原有数据库信息，并发出不一致预警。 2. HS数据AI智能分类： -.利用数据库内的料号和料号描述信息 -通过自有算法、深度机器学习或外部AI机器学习技术 -对料号进行HS code预分类 -物料号+HS code表 | E19: 安规 | F19: Bob | G19: 高 | H19: 17 | I19: 高 | J19: 平台 | K19: 材料上传 | L19: 20 | M19: =LEFT(U19,4) -> 2526 | N19: =L19*330 -> 6600 | O19: =N19*0.2 -> 1320 | P19: 100 | Q19: =N19 -> 6600 | R19: =SUM(O19) -> 1320 | S19: =P19*0.5 -> 50 | T19: Smart GTC Management V2 | U19: 2526 Q3 | X19: =IF( Table1[[#This Row],[ID]] = 0, "Cancelled", IF( Table1[[#This Row],[交付YRQTR]] = "TBD", "TBD", IF( ISBLANK(Table1[[#This Row],[计划开始时间]]), "Not Started", IF( AND( NOT(ISBLANK(Table1[[#This Row],[计划开始时间]])), Table1[[#This Row],[计划开始时间]] <= TODAY(), NOT(ISBLANK(Table1[[#This Row],[结束日期]])), Table1[[#This Row],[结束日期]] <= TODAY() ), "Completed", IF( OR( AND( Table1[[#This Row],[计划开始时间]] <= TODAY(), ISBLANK(Table1[[#This Row],[结束日期]]) ), AND( Table1[[#This Row],[计划开始时间]] <= TODAY(), Table1[[#This Row],[结束日期]] >= TODAY() ) ), "In Progress", "Not Started" ) ) ) )) -> Cancelled | AF19: FY2526 Q3 | AH19: =IF(Table1[[#This Row],[Dev Pmt]]="",Table1[[#This Row],[YR0 开发费用]]-0,Table1[[#This Row],[YR0 开发费用]]-Table1[[#This Row],[Dev Pmt]]) -> 6600
A20: 0 | B20: Compliance | C20: Smart GTC Management V3 | D20: 开展AI信息识别和抓取报关单信息，并比对原有数据库信息，并发出不一致预警。 3. HS数据AI智能分类： -.利用数据库内的料号和料号描述信息 -通过自有算法、深度机器学习或外部AI机器学习技术 -对料号进行HS code预分类 -物料号+HS code表 | E20: 安规 | F20: Bob | G20: 高 | H20: 17 | I20: 高 | J20: 平台 | K20: AI预警 | L20: 20 | M20: =LEFT(U20,4) -> 2526 | N20: =L20*330 -> 6600 | O20: =N20*0.2 -> 1320 | P20: 100 | Q20: =N20 -> 6600 | R20: =SUM(O20) -> 1320 | S20: =P20*0.5 -> 50 | T20: Smart GTC Management V3 | U20: 2526 Q3 | X20: =IF( Table1[[#This Row],[ID]] = 0, "Cancelled", IF( Table1[[#This Row],[交付YRQTR]] = "TBD", "TBD", IF( ISBLANK(Table1[[#This Row],[计划开始时间]]), "Not Started", IF( AND( NOT(ISBLANK(Table1[[#This Row],[计划开始时间]])), Table1[[#This Row],[计划开始时间]] <= TODAY(), NOT(ISBLANK(Table1[[#This Row],[结束日期]])), Table1[[#This Row],[结束日期]] <= TODAY() ), "Completed", IF( OR( AND( Table1[[#This Row],[计划开始时间]] <= TODAY(), ISBLANK(Table1[[#This Row],[结束日期]]) ), AND( Table1[[#This Row],[计划开始时间]] <= TODAY(), Table1[[#This Row],[结束日期]] >= TODAY() ) ), "In Progress", "Not Started" ) ) ) )) -> Cancelled | AF20: FY2526 Q3 | AH20: =IF(Table1[[#This Row],[Dev Pmt]]="",Table1[[#This Row],[YR0 开发费用]]-0,Table1[[#This Row],[YR0 开发费用]]-Table1[[#This Row],[Dev Pmt]]) -> 6600
A21: 0 | B21: Data | C21: Logistics Smart KM | D21: Logistics Smart KM 物流知识管理平台（文档向量化，数据库化）： 1.基于OCR技术，利用LLM大模型对各种文档（发票，清关文件）进行处理。 2.首先将现有的非结构化文档（如发票、清关文件等）整合到一个量化的数据库中。 3.开发一个可配置的平台，以满足不同场景的需求。 4.利用OpenAI模型，通过不同类型的文档OCR结果创建知识库。 | E21: 物流 | F21: Kevin | G21: 中 | H21: 25 | I21: 高 | J21: 平台 | L21: 60 | M21: =LEFT(U21,4) -> 2526 | N21: =L21*330 -> 19800 | O21: =N21*0.2 -> 3960 | P21: 100 | Q21: =N21 -> 19800 | R21: =SUM(O21) -> 3960 | S21: =P21*0.5 -> 50 | T21: Logistics Smart Knowledge Management | U21: 2526 Q4 | X21: =IF( Table1[[#This Row],[ID]] = 0, "Cancelled", IF( Table1[[#This Row],[交付YRQTR]] = "TBD", "TBD", IF( ISBLANK(Table1[[#This Row],[计划开始时间]]), "Not Started", IF( AND( NOT(ISBLANK(Table1[[#This Row],[计划开始时间]])), Table1[[#This Row],[计划开始时间]] <= TODAY(), NOT(ISBLANK(Table1[[#This Row],[结束日期]])), Table1[[#This Row],[结束日期]] <= TODAY() ), "Completed", IF( OR( AND( Table1[[#This Row],[计划开始时间]] <= TODAY(), ISBLANK(Table1[[#This Row],[结束日期]]) ), AND( Table1[[#This Row],[计划开始时间]] <= TODAY(), Table1[[#This Row],[结束日期]] >= TODAY() ) ), "In Progress", "Not Started" ) ) ) )) -> Cancelled | AF21: FY2526 Q3 | AH21: =IF(Table1[[#This Row],[Dev Pmt]]="",Table1[[#This Row],[YR0 开发费用]]-0,Table1[[#This Row],[YR0 开发费用]]-Table1[[#This Row],[Dev Pmt]]) -> 19800
A22: 0 | B22: Cost | C22: 智能成本预测模型 | D22: 1、CPP价格查询平台，异常数据收集，价格汇总 2、依据CPP历史数据，通过输入起止点、终点，预测成本最优路线，并展示在每个仓库的费用。 | E22: 成本 | F22: Cheryl | G22: 高 | H22: 23 | I22: 中 | J22: 平台 | L22: 50 | M22: =LEFT(U22,4) -> 2526 | N22: =L22*330 -> 16500 | O22: =N22*0.2 -> 3300 | P22: 100 | Q22: =N22 -> 16500 | R22: =SUM(O22) -> 3300 | S22: =P22*0.5 -> 50 | T22: Intelligent Cost Prediction Mode | U22: 2526 Q3 | X22: =IF( Table1[[#This Row],[ID]] = 0, "Cancelled", IF( Table1[[#This Row],[交付YRQTR]] = "TBD", "TBD", IF( ISBLANK(Table1[[#This Row],[计划开始时间]]), "Not Started", IF( AND( NOT(ISBLANK(Table1[[#This Row],[计划开始时间]])), Table1[[#This Row],[计划开始时间]] <= TODAY(), NOT(ISBLANK(Table1[[#This Row],[结束日期]])), Table1[[#This Row],[结束日期]] <= TODAY() ), "Completed", IF( OR( AND( Table1[[#This Row],[计划开始时间]] <= TODAY(), ISBLANK(Table1[[#This Row],[结束日期]]) ), AND( Table1[[#This Row],[计划开始时间]] <= TODAY(), Table1[[#This Row],[结束日期]] >= TODAY() ) ), "In Progress", "Not Started" ) ) ) )) -> Cancelled | AF22: FY2526 Q3 | AH22: =IF(Table1[[#This Row],[Dev Pmt]]="",Table1[[#This Row],[YR0 开发费用]]-0,Table1[[#This Row],[YR0 开发费用]]-Table1[[#This Row],[Dev Pmt]]) -> 16500
A23: 0 | B23: Cost | C23: Exceptions diagnosis | D23: （1）历史数据量级是千万级，有自己的数据库，历史数据需要人工标注再输入模型 （2）依据历史数据分析某个月份价格波动的原因：成本中心变动、关税加增或者其他原因 （3）依据历史包裹物流路线方案，分析目前物流方案是否是最优方案，若否，推荐成本最优的物流路线方案（时间最短、成本最少） | E23: 成本 | F23: Cheryl | G23: 高 | I23: 高 | J23: 平台 | K23: 资源和需求还需要讨论55 | M23: =LEFT(U23,4) -> TBD | N23: =L23*360 -> 0 | O23: =N23*0.2 -> 0 | P23: 100 | Q23: =N23*0.7 -> 0 | R23: =SUM(O23) -> 0 | S23: 0 | T23: Exceptions diagnosis | U23: TBD | X23: =IF( Table1[[#This Row],[ID]] = 0, "Cancelled", IF( Table1[[#This Row],[交付YRQTR]] = "TBD", "TBD", IF( ISBLANK(Table1[[#This Row],[计划开始时间]]), "Not Started", IF( AND( NOT(ISBLANK(Table1[[#This Row],[计划开始时间]])), Table1[[#This Row],[计划开始时间]] <= TODAY(), NOT(ISBLANK(Table1[[#This Row],[结束日期]])), Table1[[#This Row],[结束日期]] <= TODAY() ), "Completed", IF( OR( AND( Table1[[#This Row],[计划开始时间]] <= TODAY(), ISBLANK(Table1[[#This Row],[结束日期]]) ), AND( Table1[[#This Row],[计划开始时间]] <= TODAY(), Table1[[#This Row],[结束日期]] >= TODAY() ) ), "In Progress", "Not Started" ) ) ) )) -> Cancelled | AH23: =IF(Table1[[#This Row],[Dev Pmt]]="",Table1[[#This Row],[YR0 开发费用]]-0,Table1[[#This Row],[YR0 开发费用]]-Table1[[#This Row],[Dev Pmt]]) -> 0
A24: 0 | B24: Warehouse | C24: LogiAgent PBI相关开发 | D24: 建设统一PBI智能问数平台，优化Intellidata流程，支持AIForce工作流、可视化洞察、报表导出及Agent编排能力，实现数据查询、分析洞察到智能执行的端到端闭环。 | E24: 物流 | F24: Hanson | L24: 120 | M24: 2627 | N24: =L24*330 -> 39600 | O24: =N24*0.2 -> 7920 | P24: 100 | Q24: =N24 -> 39600 | R24: =SUM(O24) -> 7920 | S24: =P24*0.5 -> 50 | T24: SupplyX 3.0 | U24: 2627Q1 | X24: Canceled | AB24: =Table1[[#This Row],[YR0 开发费用]] -> 39600 | AC24: 46155 | AF24: FY2526 Q4 | AH24: =IF(Table1[[#This Row],[Dev Pmt]]="",Table1[[#This Row],[YR0 开发费用]]-0,Table1[[#This Row],[YR0 开发费用]]-Table1[[#This Row],[Dev Pmt]]) -> 0
A25: 1 | B25: Warehouse | C25: 3PL运输账单比对 | D25: 实现IDG/ISG事业部入库运输账单与3PL供应商账单的自动化比对。系统将自动生成13种内部运输账单，并与3PL账单进行智能匹配，解决人工核对效率低、易出错的问题。通过标准化关键业务规则和建立自动化流程，预计可提升对账效率70%。 核心功能 自动生成13种业务账单 智能匹配与差异标识 关键规则标准化处理 异常数据自动预警 | E25: 运输 | F25: Yuchang | G25: 中 | H25: 11 | I25: 低 | J25: 自动化 | L25: 12 | M25: =LEFT(U25,4) -> 2526 | N25: =L25*330 -> 3960 | O25: =N25*0.2 -> 792 | P25: 100 | Q25: =N25*0.7 -> 2772 | R25: =SUM(O25) -> 792 | S25: =P25*0.5 -> 50 | T25: 3PL Transport Bill Comparison | U25: =IF(OR(ISBLANK(Table1[[#This Row],[起始日期]]),Table1[[#This Row],[起始日期]]=""),RIGHT(YEAR(EDATE(Table1[[#This Row],[计划开始时间]],-3)),2) & RIGHT(YEAR(EDATE(Table1[[#This Row],[计划开始时间]],-3))+1,2) & " Q" & ROUNDUP(MONTH(EDATE(Table1[[#This Row],[计划开始时间]],-3))/3,0),RIGHT(YEAR(EDATE(Table1[[#This Row],[起始日期]],-3)),2) & RIGHT(YEAR(EDATE(Table1[[#This Row],[起始日期]],-3))+1,2) & " Q" & ROUNDUP(MONTH(EDATE(Table1[[#This Row],[起始日期]],-3))/3,0)) -> 2526 Q1 | V25: 45757 | W25: 45869 | X25: =IF( Table1[[#This Row],[ID]] = 0, "Cancelled", IF( Table1[[#This Row],[交付YRQTR]] = "TBD", "TBD", IF( ISBLANK(Table1[[#This Row],[计划开始时间]]), "Not Started", IF( AND( NOT(ISBLANK(Table1[[#This Row],[计划开始时间]])), Table1[[#This Row],[计划开始时间]] <= TODAY(), NOT(ISBLANK(Table1[[#This Row],[结束日期]])), Table1[[#This Row],[结束日期]] <= TODAY() ), "Completed", IF( OR( AND( Table1[[#This Row],[计划开始时间]] <= TODAY(), ISBLANK(Table1[[#This Row],[结束日期]]) ), AND( Table1[[#This Row],[计划开始时间]] <= TODAY(), Table1[[#This Row],[结束日期]] >= TODAY() ) ), "In Progress", "Not Started" ) ) ) )) -> Completed | Y25: 由于插入请章的需求，以及3pl加入一些新的修改，3pl需求开发进度有延迟。 | Z25: 45754 | AA25: 45869 | AB25: =Table1[[#This Row],[YR0 开发费用]] -> 2772 | AC25: 45776 | AF25: FY2526 Q1 | AH25: =IF(Table1[[#This Row],[Dev Pmt]]="",Table1[[#This Row],[YR0 开发费用]]-0,Table1[[#This Row],[YR0 开发费用]]-Table1[[#This Row],[Dev Pmt]]) -> 0
A26: 2 | B26: Warehouse | C26: 定期邮箱发送库存DB报告 | D26: 定期自动发送指定日期的库存报表,并根据报表图片内容进行解析和输出文字说明 | E26: 库存 | F26: Hanson | G26: 高 | H26: 1 | I26: 低 | J26: 自动化 | L26: 15 | M26: =LEFT(U26,4) -> 2425 | N26: =L26*360 -> 5400 | O26: =N26*0.2 -> 1080 | P26: 100 | Q26: =N26*0.7 -> 3780 | R26: =SUM(O26) -> 1080 | S26: =P26*0.5 -> 50 | T26: Automated Email for Inventory DB Reports | U26: =IF(OR(ISBLANK(Table1[[#This Row],[起始日期]]),Table1[[#This Row],[起始日期]]=""),RIGHT(YEAR(EDATE(Table1[[#This Row],[计划开始时间]],-3)),2) & RIGHT(YEAR(EDATE(Table1[[#This Row],[计划开始时间]],-3))+1,2) & " Q" & ROUNDUP(MONTH(EDATE(Table1[[#This Row],[计划开始时间]],-3))/3,0),RIGHT(YEAR(EDATE(Table1[[#This Row],[起始日期]],-3)),2) & RIGHT(YEAR(EDATE(Table1[[#This Row],[起始日期]],-3))+1,2) & " Q" & ROUNDUP(MONTH(EDATE(Table1[[#This Row],[起始日期]],-3))/3,0)) -> 2425 Q2 | V26: 45505 | W26: 45545 | X26: =IF( Table1[[#This Row],[ID]] = 0, "Cancelled", IF( Table1[[#This Row],[交付YRQTR]] = "TBD", "TBD", IF( ISBLANK(Table1[[#This Row],[计划开始时间]]), "Not Started", IF( AND( NOT(ISBLANK(Table1[[#This Row],[计划开始时间]])), Table1[[#This Row],[计划开始时间]] <= TODAY(), NOT(ISBLANK(Table1[[#This Row],[结束日期]])), Table1[[#This Row],[结束日期]] <= TODAY() ), "Completed", IF( OR( AND( Table1[[#This Row],[计划开始时间]] <= TODAY(), ISBLANK(Table1[[#This Row],[结束日期]]) ), AND( Table1[[#This Row],[计划开始时间]] <= TODAY(), Table1[[#This Row],[结束日期]] >= TODAY() ) ), "In Progress", "Not Started" ) ) ) )) -> Completed | Y26: 用户需求的变化导致项目范围扩大和调整；遇到预料之外的技术问题或挑战。 | Z26: 45505 | AA26: 45536 | AB26: =Table1[[#This Row],[YR0 开发费用]] -> 3780 | AC26: 45562 | AD26: 1130 | AE26: 45776 | AF26: FY2425 Q2 | AH26: =IF(Table1[[#This Row],[Dev Pmt]]="",Table1[[#This Row],[YR0 开发费用]]-0,Table1[[#This Row],[YR0 开发费用]]-Table1[[#This Row],[Dev Pmt]]) -> 0
A27: 3 | B27: Warehouse | C27: 电池主数据平台 V1 | D27: 开发一个结合四个BU的电池信息查询平台，PCG数据自动抓取和生成电池PN的自动化流程 | E27: 电池 | F27: Fay, Jinjin, Rooney | G27: 高 | H27: 3 | I27: 中 | J27: 平台 | K27: 第一期：权限管理（默认物流有权限、其他人需申请权限、super user）、数据查询、数据下载(PCG、TAB\MBG\ISG) | L27: 20 | M27: =LEFT(U27,4) -> 2425 | N27: =L27*360 -> 7200 | O27: =N27*0.2 -> 1440 | P27: 100 | Q27: =N27*0.7 -> 5040 | R27: =SUM(O27) -> 1440 | S27: =P27*0.5 -> 50 | T27: Battery Master Data Platform V1 | U27: =IF(OR(ISBLANK(Table1[[#This Row],[起始日期]]),Table1[[#This Row],[起始日期]]=""),RIGHT(YEAR(EDATE(Table1[[#This Row],[计划开始时间]],-3)),2) & RIGHT(YEAR(EDATE(Table1[[#This Row],[计划开始时间]],-3))+1,2) & " Q" & ROUNDUP(MONTH(EDATE(Table1[[#This Row],[计划开始时间]],-3))/3,0),RIGHT(YEAR(EDATE(Table1[[#This Row],[起始日期]],-3)),2) & RIGHT(YEAR(EDATE(Table1[[#This Row],[起始日期]],-3))+1,2) & " Q" & ROUNDUP(MONTH(EDATE(Table1[[#This Row],[起始日期]],-3))/3,0)) -> 2425 Q3 | V27: 45581 | W27: 45705 | X27: =IF( Table1[[#This Row],[ID]] = 0, "Cancelled", IF( Table1[[#This Row],[交付YRQTR]] = "TBD", "TBD", IF( ISBLANK(Table1[[#This Row],[计划开始时间]]), "Not Started", IF( AND( NOT(ISBLANK(Table1[[#This Row],[计划开始时间]])), Table1[[#This Row],[计划开始时间]] <= TODAY(), NOT(ISBLANK(Table1[[#This Row],[结束日期]])), Table1[[#This Row],[结束日期]] <= TODAY() ), "Completed", IF( OR( AND( Table1[[#This Row],[计划开始时间]] <= TODAY(), ISBLANK(Table1[[#This Row],[结束日期]]) ), AND( Table1[[#This Row],[计划开始时间]] <= TODAY(), Table1[[#This Row],[结束日期]] >= TODAY() ) ), "In Progress", "Not Started" ) ) ) )) -> Completed | Y27: 因为前一阶段的工作未能按时完成，人力资源不足导致后续工作的推迟，再有前期需求调研及ADFS认证资料准备也占用一些时间。 | Z27: 45573 | AA27: 46006 | AB27: 5040 | AC27: 45562 | AD27: 1490 | AE27: 45776 | AF27: FY2425 Q2 | AH27: =IF(Table1[[#This Row],[Dev Pmt]]="",Table1[[#This Row],[YR0 开发费用]]-0,Table1[[#This Row],[YR0 开发费用]]-Table1[[#This Row],[Dev Pmt]]) -> 0
A28: 3 | B28: Warehouse | C28: 电池主数据平台 V2 | D28: 开发一个结合四个BU的电池信息查询平台，MBG和ISG数据自动抓取和生成电池PN的自动化流程 | E28: 电池 | F28: All | G28: 高 | H28: 19 | I28: 中 | J28: 平台 | K28: 第二期：证书下载，图片上传 | L28: 30 | M28: =LEFT(U28,4) -> 2526 | N28: =L28*330 -> 9900 | O28: =N28*0.2 -> 1980 | P28: 100 | Q28: =N28*0.7 -> 6930 | R28: =SUM(O28) -> 1980 | S28: =P28*0.5 -> 50 | T28: Battery Master Data Platform V2 | U28: =IF(OR(ISBLANK(Table1[[#This Row],[起始日期]]),Table1[[#This Row],[起始日期]]=""),RIGHT(YEAR(EDATE(Table1[[#This Row],[计划开始时间]],-3)),2) & RIGHT(YEAR(EDATE(Table1[[#This Row],[计划开始时间]],-3))+1,2) & " Q" & ROUNDUP(MONTH(EDATE(Table1[[#This Row],[计划开始时间]],-3))/3,0),RIGHT(YEAR(EDATE(Table1[[#This Row],[起始日期]],-3)),2) & RIGHT(YEAR(EDATE(Table1[[#This Row],[起始日期]],-3))+1,2) & " Q" & ROUNDUP(MONTH(EDATE(Table1[[#This Row],[起始日期]],-3))/3,0)) -> 2526 Q1 | V28: 45796 | W28: 45905 | X28: =IF( Table1[[#This Row],[ID]] = 0, "Cancelled", IF( Table1[[#This Row],[交付YRQTR]] = "TBD", "TBD", IF( ISBLANK(Table1[[#This Row],[计划开始时间]]), "Not Started", IF( AND( NOT(ISBLANK(Table1[[#This Row],[计划开始时间]])), Table1[[#This Row],[计划开始时间]] <= TODAY(), NOT(ISBLANK(Table1[[#This Row],[结束日期]])), Table1[[#This Row],[结束日期]] <= TODAY() ), "Completed", IF( OR( AND( Table1[[#This Row],[计划开始时间]] <= TODAY(), ISBLANK(Table1[[#This Row],[结束日期]]) ), AND( Table1[[#This Row],[计划开始时间]] <= TODAY(), Table1[[#This Row],[结束日期]] >= TODAY() ) ), "In Progress", "Not Started" ) ) ) )) -> Completed | Y28: 因为前一阶段的工作未能按时完成，人力资源不足导致后续工作的推迟。 | Z28: 45796 | AA28: 45905 | AB28: =Table1[[#This Row],[YR0 开发费用]] -> 6930 | AC28: 45776 | AF28: FY2526 Q1 | AH28: =IF(Table1[[#This Row],[Dev Pmt]]="",Table1[[#This Row],[YR0 开发费用]]-0,Table1[[#This Row],[YR0 开发费用]]-Table1[[#This Row],[Dev Pmt]]) -> 0
A29: 3 | B29: Warehouse | C29: 电池主数据平台 V3 | D29: TAB 相关功能开发，所有BU的优化，以及权限这块重新设计有BU的优化，以及权限这块重新设计 | E29: 电池 | F29: Tianyu | G29: 高 | I29: 中 | J29: 平台 | L29: 55 | M29: 2627 | N29: =L29*330 -> 18150 | O29: =N29*0.2 -> 3630 | P29: 100 | Q29: =N29 -> 18150 | R29: =SUM(O29) -> 3630 | S29: =P29*0.5 -> 50 | T29: Battery Master Data Platform V3 | U29: =IF(OR(ISBLANK(Table1[[#This Row],[起始日期]]),Table1[[#This Row],[起始日期]]=""),RIGHT(YEAR(EDATE(Table1[[#This Row],[计划开始时间]],-3)),2) & RIGHT(YEAR(EDATE(Table1[[#This Row],[计划开始时间]],-3))+1,2) & " Q" & ROUNDUP(MONTH(EDATE(Table1[[#This Row],[计划开始时间]],-3))/3,0),RIGHT(YEAR(EDATE(Table1[[#This Row],[起始日期]],-3)),2) & RIGHT(YEAR(EDATE(Table1[[#This Row],[起始日期]],-3))+1,2) & " Q" & ROUNDUP(MONTH(EDATE(Table1[[#This Row],[起始日期]],-3))/3,0)) -> 2526 Q4 | X29: =IF( Table1[[#This Row],[ID]] = 0, "Cancelled", IF( Table1[[#This Row],[交付YRQTR]] = "TBD", "TBD", IF( ISBLANK(Table1[[#This Row],[计划开始时间]]), "Not Started", IF( AND( NOT(ISBLANK(Table1[[#This Row],[计划开始时间]])), Table1[[#This Row],[计划开始时间]] <= TODAY(), NOT(ISBLANK(Table1[[#This Row],[结束日期]])), Table1[[#This Row],[结束日期]] <= TODAY() ), "Completed", IF( OR( AND( Table1[[#This Row],[计划开始时间]] <= TODAY(), ISBLANK(Table1[[#This Row],[结束日期]]) ), AND( Table1[[#This Row],[计划开始时间]] <= TODAY(), Table1[[#This Row],[结束日期]] >= TODAY() ) ), "In Progress", "Not Started" ) ) ) )) -> In Progress | Z29: 46105 | AA29: 46173 | AC29: 46155 | AF29: =VLOOKUP(Table1[[#This Row],[Task Name]],[1]AI_Jenny!$B$60:$E$99,4,0) -> #N/A | AH29: =IF(Table1[[#This Row],[Dev Pmt]]="",Table1[[#This Row],[YR0 开发费用]]-0,Table1[[#This Row],[YR0 开发费用]]-Table1[[#This Row],[Dev Pmt]]) -> 18150
A30: 4 | B30: Warehouse | C30: 电池证书识别 V3 | D30: 针对没有空海运鉴定证书 | E30: 电池 | F30: All | G30: 高 | I30: 中 | J30: 自动化 | L30: 20 | M30: =LEFT(U30,4) -> 2526 | N30: =L30*330 -> 6600 | O30: =N30*0.2 -> 1320 | P30: 100 | Q30: =N30 -> 6600 | R30: =SUM(O30) -> 1320 | S30: =P30*0.5 -> 50 | T30: WHS Battery Certificate Management V3 | U30: 2526 Q4 | X30: =IF( Table1[[#This Row],[ID]] = 0, "Cancelled", IF( Table1[[#This Row],[交付YRQTR]] = "TBD", "TBD", IF( ISBLANK(Table1[[#This Row],[计划开始时间]]), "Not Started", IF( AND( NOT(ISBLANK(Table1[[#This Row],[计划开始时间]])), Table1[[#This Row],[计划开始时间]] <= TODAY(), NOT(ISBLANK(Table1[[#This Row],[结束日期]])), Table1[[#This Row],[结束日期]] <= TODAY() ), "Completed", IF( OR( AND( Table1[[#This Row],[计划开始时间]] <= TODAY(), ISBLANK(Table1[[#This Row],[结束日期]]) ), AND( Table1[[#This Row],[计划开始时间]] <= TODAY(), Table1[[#This Row],[结束日期]] >= TODAY() ) ), "In Progress", "Not Started" ) ) ) )) -> Not Started | AB30: 6600 | AC30: 46038 | AF30: FY2526 Q3 | AH30: =IF(Table1[[#This Row],[Dev Pmt]]="",Table1[[#This Row],[YR0 开发费用]]-0,Table1[[#This Row],[YR0 开发费用]]-Table1[[#This Row],[Dev Pmt]]) -> 0
A31: 4 | B31: Warehouse | C31: 电池证书识别 V1 | D31: 1.根据Part Number(PN)分类 2.纯电池：7种报告是否都有，7种证书型号一致确认，厂商一致核对 设备含电池：5种证书厂商一致确认，空海运厂商一致核对 3. 识别纯电池还是设备带电池 4. 2024年section14/15要含有65th和188的字眼 5.识别证书的年份（MSDS和空海运每年有效，其余四份长期有效--- pass/fail） 6.针对设备含电池，需要确认电池的型号和品牌 7.如供应商提供的证书不全（即除空/海运证书外，另外5份没有提供全），则纯电池根据型号判断历史文件中有没有不全的证书，设备含电池根据电池型号和品牌判断、 | E31: 电池 | F31: All | G31: 高 | H31: 2 | I31: 中 | J31: 自动化 | L31: 15 | M31: =LEFT(U31,4) -> 2425 | N31: =L31*360 -> 5400 | O31: =N31*0.2 -> 1080 | P31: 100 | Q31: =N31*0.7 -> 3780 | R31: =SUM(O31) -> 1080 | S31: =P31*0.5 -> 50 | T31: WHS Battery Certificate Management V1 | U31: =IF(OR(ISBLANK(Table1[[#This Row],[起始日期]]),Table1[[#This Row],[起始日期]]=""),RIGHT(YEAR(EDATE(Table1[[#This Row],[计划开始时间]],-3)),2) & RIGHT(YEAR(EDATE(Table1[[#This Row],[计划开始时间]],-3))+1,2) & " Q" & ROUNDUP(MONTH(EDATE(Table1[[#This Row],[计划开始时间]],-3))/3,0),RIGHT(YEAR(EDATE(Table1[[#This Row],[起始日期]],-3)),2) & RIGHT(YEAR(EDATE(Table1[[#This Row],[起始日期]],-3))+1,2) & " Q" & ROUNDUP(MONTH(EDATE(Table1[[#This Row],[起始日期]],-3))/3,0)) -> 2425 Q2 | V31: 45534 | W31: 45595 | X31: =IF( Table1[[#This Row],[ID]] = 0, "Cancelled", IF( Table1[[#This Row],[交付YRQTR]] = "TBD", "TBD", IF( ISBLANK(Table1[[#This Row],[计划开始时间]]), "Not Started", IF( AND( NOT(ISBLANK(Table1[[#This Row],[计划开始时间]])), Table1[[#This Row],[计划开始时间]] <= TODAY(), NOT(ISBLANK(Table1[[#This Row],[结束日期]])), Table1[[#This Row],[结束日期]] <= TODAY() ), "Completed", IF( OR( AND( Table1[[#This Row],[计划开始时间]] <= TODAY(), ISBLANK(Table1[[#This Row],[结束日期]]) ), AND( Table1[[#This Row],[计划开始时间]] <= TODAY(), Table1[[#This Row],[结束日期]] >= TODAY() ) ), "In Progress", "Not Started" ) ) ) )) -> Completed | Y31: 用户需求的变化导致项目范围扩大和调整；技术难度较高，需要更长的研发时间；遇到了未预见的问题，如算法优化、数据清洗等。 | Z31: 45537 | AA31: 45565 | AB31: 3780 | AC31: 45562 | AD31: 1130 | AE31: 45776 | AF31: FY2425 Q2 | AH31: =IF(Table1[[#This Row],[Dev Pmt]]="",Table1[[#This Row],[YR0 开发费用]]-0,Table1[[#This Row],[YR0 开发费用]]-Table1[[#This Row],[Dev Pmt]]) -> 0
A32: 4 | B32: Warehouse | C32: 电池证书识别 V2 | D32: 针对于一个型号对应多个空海运证书 | E32: 电池 | F32: All | G32: 高 | I32: 中 | J32: 自动化 | L32: 50 | M32: =LEFT(U32,4) -> 2425 | N32: =L32*330 -> 16500 | O32: =N32*0.2 -> 3300 | P32: 100 | Q32: =N32*0.7 -> 11550 | R32: =SUM(O32) -> 3300 | S32: =P32*0.5 -> 50 | T32: WHS Battery Certificate Management V2 | U32: =IF(OR(ISBLANK(Table1[[#This Row],[起始日期]]),Table1[[#This Row],[起始日期]]=""),RIGHT(YEAR(EDATE(Table1[[#This Row],[计划开始时间]],-3)),2) & RIGHT(YEAR(EDATE(Table1[[#This Row],[计划开始时间]],-3))+1,2) & " Q" & ROUNDUP(MONTH(EDATE(Table1[[#This Row],[计划开始时间]],-3))/3,0),RIGHT(YEAR(EDATE(Table1[[#This Row],[起始日期]],-3)),2) & RIGHT(YEAR(EDATE(Table1[[#This Row],[起始日期]],-3))+1,2) & " Q" & ROUNDUP(MONTH(EDATE(Table1[[#This Row],[起始日期]],-3))/3,0)) -> 2425 Q4 | V32: 45707 | W32: 45793 | X32: =IF( Table1[[#This Row],[ID]] = 0, "Cancelled", IF( Table1[[#This Row],[交付YRQTR]] = "TBD", "TBD", IF( ISBLANK(Table1[[#This Row],[计划开始时间]]), "Not Started", IF( AND( NOT(ISBLANK(Table1[[#This Row],[计划开始时间]])), Table1[[#This Row],[计划开始时间]] <= TODAY(), NOT(ISBLANK(Table1[[#This Row],[结束日期]])), Table1[[#This Row],[结束日期]] <= TODAY() ), "Completed", IF( OR( AND( Table1[[#This Row],[计划开始时间]] <= TODAY(), ISBLANK(Table1[[#This Row],[结束日期]]) ), AND( Table1[[#This Row],[计划开始时间]] <= TODAY(), Table1[[#This Row],[结束日期]] >= TODAY() ) ), "In Progress", "Not Started" ) ) ) )) -> Completed | Y32: 因为前一阶段的工作未能按时完成，人力资源不足导致后续工作的推迟。 | Z32: 45707 | AA32: 45793 | AB32: =Table1[[#This Row],[YR0 开发费用]] -> 11550 | AC32: 45776 | AF32: FY2526 Q1 | AH32: =IF(Table1[[#This Row],[Dev Pmt]]="",Table1[[#This Row],[YR0 开发费用]]-0,Table1[[#This Row],[YR0 开发费用]]-Table1[[#This Row],[Dev Pmt]]) -> 0
A33: 5 | B33: Warehouse | C33: 电池供应商自动邮件 | D33: 系统监测缺失的电池文件和电池相关问题自动给供应商发邮件让其补充 1. 电池证书识别Version 1 完成后，在缺少证书或者证书识别错误的情况下，自动发邮件给供应商，邮件里面含电池的型号和电池厂商，以及证书审核后问题（缺失或者错误）。供应商补充证书，loop系统发的邮件。系统检测到供应商的邮件，获取邮件里的证书，保存到原始的文件目录下，再次审核。 2.在电池证书第一阶段（Version 1）检测到一个PN下多个型号（多个电池型号和厂商）的证书问题，需要（Lingling) 人工审核干预，她自己审核文件并判断是否缺少证书或者证书是否有问题，如有问题手动触发自动邮件给供应商。 后续可能需要以Part Number和供应商Vendor和品牌三种类别去命名 3.待Version2 完成后，就可以去掉多个电池型号厂商的PN需要LingLing人工审核的步骤。 | E33: 电池 | F33: Fay, Jinjin, Rooney | G33: 高 | H33: 4 | I33: 低 | J33: 自动化 | L33: 5 | M33: =LEFT(U33,4) -> 2526 | N33: =L33*360 -> 1800 | O33: =N33*0.2 -> 360 | P33: 100 | Q33: =N33*0.7 -> 1260 | R33: =SUM(O33) -> 360 | S33: =P33*0.5 -> 50 | T33: Automated Emails for Battery Suppliers | U33: =IF(OR(ISBLANK(Table1[[#This Row],[起始日期]]),Table1[[#This Row],[起始日期]]=""),RIGHT(YEAR(EDATE(Table1[[#This Row],[计划开始时间]],-3)),2) & RIGHT(YEAR(EDATE(Table1[[#This Row],[计划开始时间]],-3))+1,2) & " Q" & ROUNDUP(MONTH(EDATE(Table1[[#This Row],[计划开始时间]],-3))/3,0),RIGHT(YEAR(EDATE(Table1[[#This Row],[起始日期]],-3)),2) & RIGHT(YEAR(EDATE(Table1[[#This Row],[起始日期]],-3))+1,2) & " Q" & ROUNDUP(MONTH(EDATE(Table1[[#This Row],[起始日期]],-3))/3,0)) -> 2526 Q1 | V33: 45812 | W33: 45905 | X33: =IF( Table1[[#This Row],[ID]] = 0, "Cancelled", IF( Table1[[#This Row],[交付YRQTR]] = "TBD", "TBD", IF( ISBLANK(Table1[[#This Row],[计划开始时间]]), "Not Started", IF( AND( NOT(ISBLANK(Table1[[#This Row],[计划开始时间]])), Table1[[#This Row],[计划开始时间]] <= TODAY(), NOT(ISBLANK(Table1[[#This Row],[结束日期]])), Table1[[#This Row],[结束日期]] <= TODAY() ), "Completed", IF( OR( AND( Table1[[#This Row],[计划开始时间]] <= TODAY(), ISBLANK(Table1[[#This Row],[结束日期]]) ), AND( Table1[[#This Row],[计划开始时间]] <= TODAY(), Table1[[#This Row],[结束日期]] >= TODAY() ) ), "In Progress", "Not Started" ) ) ) )) -> Completed | Z33: 45812 | AA33: 45905 | AB33: 1260 | AC33: 45562 | AF33: FY2425 Q2 | AH33: =IF(Table1[[#This Row],[Dev Pmt]]="",Table1[[#This Row],[YR0 开发费用]]-0,Table1[[#This Row],[YR0 开发费用]]-Table1[[#This Row],[Dev Pmt]]) -> 0
A34: 6 | B34: Warehouse | C34: 备件物流AI问答机器人 V3 | D34: SupplyX skill+ 2.0补丁 | E34: 物流 | F34: Hanson | G34: 高 | H34: 21 | I34: 中 | J34: 平台 | K34: 第二期：依据物流行业知识回答物流延迟、停滞的原因 参考SCI知识平台 | L34: 105 | M34: 2627 | N34: =L34*330 -> 34650 | O34: =N34*0.2 -> 6930 | P34: 100 | Q34: =N34 -> 34650 | R34: =SUM(O34) -> 6930 | S34: =P34*0.5 -> 50 | T34: SupplyX 3.0 | U34: 2627 Q1 | V34: 45799 | AB34: =Table1[[#This Row],[YR0 开发费用]] -> 34650 | AC34: 46232 | AF34: =VLOOKUP(Table1[[#This Row],[Task Name]],[1]AI_Jenny!$B$60:$E$99,4,0) -> #N/A | AH34: =IF(Table1[[#This Row],[Dev Pmt]]="",Table1[[#This Row],[YR0 开发费用]]-0,Table1[[#This Row],[YR0 开发费用]]-Table1[[#This Row],[Dev Pmt]]) -> 0
A35: 6 | B35: Warehouse | C35: 备件物流AI问答机器人 V2 | D35: LogiAgent升级版： 自动做任务， 自动生成报表和触发alert邮件 | E35: 物流 | F35: Hanson | G35: 高 | H35: 21 | I35: 中 | J35: 平台 | K35: 第二期：依据物流行业知识回答物流延迟、停滞的原因 参考SCI知识平台 | L35: 180 | M35: =LEFT(U35,4) -> 2526 | N35: =L35*400 -> 72000 | O35: =N35*0.2 -> 14400 | P35: 100 | Q35: =N35 -> 72000 | R35: =SUM(O35) -> 14400 | S35: =P35 -> 100 | T35: SSC Logistics LogiAgent V2 | U35: =IF(OR(ISBLANK(Table1[[#This Row],[起始日期]]),Table1[[#This Row],[起始日期]]=""),RIGHT(YEAR(EDATE(Table1[[#This Row],[计划开始时间]],-3)),2) & RIGHT(YEAR(EDATE(Table1[[#This Row],[计划开始时间]],-3))+1,2) & " Q" & ROUNDUP(MONTH(EDATE(Table1[[#This Row],[计划开始时间]],-3))/3,0),RIGHT(YEAR(EDATE(Table1[[#This Row],[起始日期]],-3)),2) & RIGHT(YEAR(EDATE(Table1[[#This Row],[起始日期]],-3))+1,2) & " Q" & ROUNDUP(MONTH(EDATE(Table1[[#This Row],[起始日期]],-3))/3,0)) -> 2526 Q1 | V35: 45820 | W35: 45798 | X35: =IF( Table1[[#This Row],[ID]] = 0, "Cancelled", IF( Table1[[#This Row],[交付YRQTR]] = "TBD", "TBD", IF( ISBLANK(Table1[[#This Row],[计划开始时间]]), "Not Started", IF( AND( NOT(ISBLANK(Table1[[#This Row],[计划开始时间]])), Table1[[#This Row],[计划开始时间]] <= TODAY(), NOT(ISBLANK(Table1[[#This Row],[结束日期]])), Table1[[#This Row],[结束日期]] <= TODAY() ), "Completed", IF( OR( AND( Table1[[#This Row],[计划开始时间]] <= TODAY(), ISBLANK(Table1[[#This Row],[结束日期]]) ), AND( Table1[[#This Row],[计划开始时间]] <= TODAY(), Table1[[#This Row],[结束日期]] >= TODAY() ) ), "In Progress", "Not Started" ) ) ) )) -> Completed | Z35: 45820 | AA35: 45930 | AB35: 22000 | AC35: 45954 | AF35: FY2526 Q3 | AH35: =IF(Table1[[#This Row],[Dev Pmt]]="",Table1[[#This Row],[YR0 开发费用]]-0,Table1[[#This Row],[YR0 开发费用]]-Table1[[#This Row],[Dev Pmt]]) -> 50000
A36: 6 | B36: Warehouse | C36: 备件物流AI问答机器人 V1 | D36: 开发基于AI对话模式的实时运输和货物仓库状态查询功能： 1.通过询问货物订单，从数据库输出相应的货物状态。 2.AMS系统与数据库连接，数据库物流信息会有延迟，需从第三方网站获取信息。 3.支持查询shipment的PO、BOL等信息，包括当前状态（如GRGI、打包、送货、送达等）。 4.在Teams平台上实现AI对话功能。 主要涵盖以下内容： 纯运输问题 物流Issue问题信息（如延迟原因） 物流行业知识 连接货代网站的单号跟踪功能，爬取第三方网站物流信息 数据库包含物流数据库 | E36: 物流 | F36: Hanson | G36: 高 | H36: 5 | I36: 中 | J36: 平台 | K36: teams收集信息，传给平台查询，再通过teams返回给用户物流状态及原因 第一期：集成teams AI实时查询物流状态， | L36: 70 | M36: =LEFT(U36,4) -> 2425 | N36: =L36*330 -> 23100 | O36: =N36*0.2 -> 4620 | P36: 100 | Q36: =N36+28000 -> 51100 | R36: =SUM(O36) -> 4620 | S36: =P36 -> 100 | T36: SSC Logistics LogiAgent V1 | U36: =IF(OR(ISBLANK(Table1[[#This Row],[起始日期]]),Table1[[#This Row],[起始日期]]=""),RIGHT(YEAR(EDATE(Table1[[#This Row],[计划开始时间]],-3)),2) & RIGHT(YEAR(EDATE(Table1[[#This Row],[计划开始时间]],-3))+1,2) & " Q" & ROUNDUP(MONTH(EDATE(Table1[[#This Row],[计划开始时间]],-3))/3,0),RIGHT(YEAR(EDATE(Table1[[#This Row],[起始日期]],-3)),2) & RIGHT(YEAR(EDATE(Table1[[#This Row],[起始日期]],-3))+1,2) & " Q" & ROUNDUP(MONTH(EDATE(Table1[[#This Row],[起始日期]],-3))/3,0)) -> 2425 Q3 | V36: 45601 | W36: 45819 | X36: =IF( Table1[[#This Row],[ID]] = 0, "Cancelled", IF( Table1[[#This Row],[交付YRQTR]] = "TBD", "TBD", IF( ISBLANK(Table1[[#This Row],[计划开始时间]]), "Not Started", IF( AND( NOT(ISBLANK(Table1[[#This Row],[计划开始时间]])), Table1[[#This Row],[计划开始时间]] <= TODAY(), NOT(ISBLANK(Table1[[#This Row],[结束日期]])), Table1[[#This Row],[结束日期]] <= TODAY() ), "Completed", IF( OR( AND( Table1[[#This Row],[计划开始时间]] <= TODAY(), ISBLANK(Table1[[#This Row],[结束日期]]) ), AND( Table1[[#This Row],[计划开始时间]] <= TODAY(), Table1[[#This Row],[结束日期]] >= TODAY() ) ), "In Progress", "Not Started" ) ) ) )) -> Completed | Y36: 立项延期及加入teams应用申请的新需求，导致开发周期延长。 | Z36: 45601 | AA36: 45808 | AB36: =7056+(51100-7056) -> 51100 | AC36: 45776 | AF36: FY2526 Q1 | AG36: Paid Dev 7056 on 24/9/27，paid Dev 44044 on 25/4/1 | AH36: =IF(Table1[[#This Row],[Dev Pmt]]="",Table1[[#This Row],[YR0 开发费用]]-0,Table1[[#This Row],[YR0 开发费用]]-Table1[[#This Row],[Dev Pmt]]) -> 0
A37: 6 | B37: Warehouse | C37: SupplyX 高级预警 | D37: 构建了AI驱动的主动预警系统，实现从事后监控向基于风险预测的实时预警与自动化跟进转型。 | E37: 物流 | F37: Hanson | G37: 高 | H37: 21 | I37: 中 | J37: 平台 | K37: 第二期：依据物流行业知识回答物流延迟、停滞的原因 参考SCI知识平台 | L37: 65 | M37: 2627 | N37: =L37*330 -> 21450 | O37: =N37*0.2 -> 4290 | P37: 100 | Q37: =N37 -> 21450 | R37: =SUM(O37) -> 4290 | S37: =P37*0.5 -> 50 | T37: SupplyX Intelligent Alerting | U37: 2627 Q1 | X37: =IF( Table1[[#This Row],[ID]] = 0, "Cancelled", IF( Table1[[#This Row],[交付YRQTR]] = "TBD", "TBD", IF( ISBLANK(Table1[[#This Row],[计划开始时间]]), "Not Started", IF( AND( NOT(ISBLANK(Table1[[#This Row],[计划开始时间]])), Table1[[#This Row],[计划开始时间]] <= TODAY(), NOT(ISBLANK(Table1[[#This Row],[结束日期]])), Table1[[#This Row],[结束日期]] <= TODAY() ), "Completed", IF( OR( AND( Table1[[#This Row],[计划开始时间]] <= TODAY(), ISBLANK(Table1[[#This Row],[结束日期]]) ), AND( Table1[[#This Row],[计划开始时间]] <= TODAY(), Table1[[#This Row],[结束日期]] >= TODAY() ) ), "In Progress", "Not Started" ) ) ) )) -> Not Started | AB37: =Table1[[#This Row],[YR0 开发费用]] -> 21450 | AC37: 46232 | AF37: FY2627 Q1 | AH37: =IF(Table1[[#This Row],[Dev Pmt]]="",Table1[[#This Row],[YR0 开发费用]]-0,Table1[[#This Row],[YR0 开发费用]]-Table1[[#This Row],[Dev Pmt]]) -> 0
A38: 6 | B38: Warehouse | C38: LogiAgent增强 | D38: 自然语言调用应用、查询单据、业务异常预警、用户年度行为总结 | E38: 物流 | F38: Hanson | L38: 55 | M38: 2627 | N38: =L38*330 -> 18150 | O38: =N38*0.2 -> 3630 | P38: 100 | Q38: =N38 -> 18150 | R38: =SUM(O38) -> 3630 | S38: =P38*0.5 -> 50 | T38: SupplyX 3.0 | U38: 2627Q1 | X38: In Progress | AB38: =Table1[[#This Row],[YR0 开发费用]] -> 18150 | AC38: 46155 | AF38: FY2526 Q4 | AH38: =IF(Table1[[#This Row],[Dev Pmt]]="",Table1[[#This Row],[YR0 开发费用]]-0,Table1[[#This Row],[YR0 开发费用]]-Table1[[#This Row],[Dev Pmt]]) -> 0
A39: 7 | B39: Transport | C39: 智能报价搜集平台 | D39: 1.对话框内收集需求者足够的货物基本信息，以便评估价格。 2.待业务预估运输成本后再反馈给需求者。 | E39: 运输 | F39: Brian | G39: 高 | H39: 6 | I39: 低 | J39: 平台 | K39: 方案：设置物流teams hotline support 找teams team 合作：若用户引导用户输入物料尺寸、体积、重量、地址、是否含电池、是否有相应证书等，给Brian发邮件有新单据，Brian可以在平台上找到用户需求信息，评估价格，回复用户 | L39: 24 | M39: =LEFT(U39,4) -> 2425 | N39: =L39*360 -> 8640 | O39: =N39*0.2 -> 1728 | P39: 100 | Q39: =N39*0.7 -> 6048 | R39: =SUM(O39) -> 1728 | S39: =P39*0.5 -> 50 | T39: AI-Driven Quotation Collection Platform | U39: =IF(OR(ISBLANK(Table1[[#This Row],[起始日期]]),Table1[[#This Row],[起始日期]]=""),RIGHT(YEAR(EDATE(Table1[[#This Row],[计划开始时间]],-3)),2) & RIGHT(YEAR(EDATE(Table1[[#This Row],[计划开始时间]],-3))+1,2) & " Q" & ROUNDUP(MONTH(EDATE(Table1[[#This Row],[计划开始时间]],-3))/3,0),RIGHT(YEAR(EDATE(Table1[[#This Row],[起始日期]],-3)),2) & RIGHT(YEAR(EDATE(Table1[[#This Row],[起始日期]],-3))+1,2) & " Q" & ROUNDUP(MONTH(EDATE(Table1[[#This Row],[起始日期]],-3))/3,0)) -> 2425 Q4 | V39: 45705 | W39: 45748 | X39: =IF( Table1[[#This Row],[ID]] = 0, "Cancelled", IF( Table1[[#This Row],[交付YRQTR]] = "TBD", "TBD", IF( ISBLANK(Table1[[#This Row],[计划开始时间]]), "Not Started", IF( AND( NOT(ISBLANK(Table1[[#This Row],[计划开始时间]])), Table1[[#This Row],[计划开始时间]] <= TODAY(), NOT(ISBLANK(Table1[[#This Row],[结束日期]])), Table1[[#This Row],[结束日期]] <= TODAY() ), "Completed", IF( OR( AND( Table1[[#This Row],[计划开始时间]] <= TODAY(), ISBLANK(Table1[[#This Row],[结束日期]]) ), AND( Table1[[#This Row],[计划开始时间]] <= TODAY(), Table1[[#This Row],[结束日期]] >= TODAY() ) ), "In Progress", "Not Started" ) ) ) )) -> Completed | Y39: 因添加转单的功能，开发周期变长。 | Z39: 45708 | AA39: 45729 | AB39: 6048 | AC39: 45562 | AF39: FY2425 Q2 | AH39: =IF(Table1[[#This Row],[Dev Pmt]]="",Table1[[#This Row],[YR0 开发费用]]-0,Table1[[#This Row],[YR0 开发费用]]-Table1[[#This Row],[Dev Pmt]]) -> 0
A40: 8 | B40: Sourcing | C40: Sourcing OA审批平台 | D40: 构建了一个智能化 Sourcing Rate OA 模块，通过自动审批路由、Excel 自动化和提醒机制，显著提升流程效率、合规性与灵活性。 | E40: 采购 | F40: Cynthia | L40: 30 | M40: =LEFT(U40,4) -> 2627 | N40: =L40*330 -> 9900 | O40: =N40*0.2 -> 1980 | P40: 100 | Q40: =N40 -> 9900 | R40: =SUM(O40) -> 1980 | S40: =P40*0.5 -> 50 | T40: Sourcing Rate OA Application | U40: 2627 Q1 | X40: =IF( Table1[[#This Row],[ID]] = 0, "Cancelled", IF( Table1[[#This Row],[交付YRQTR]] = "TBD", "TBD", IF( ISBLANK(Table1[[#This Row],[计划开始时间]]), "Not Started", IF( AND( NOT(ISBLANK(Table1[[#This Row],[计划开始时间]])), Table1[[#This Row],[计划开始时间]] <= TODAY(), NOT(ISBLANK(Table1[[#This Row],[结束日期]])), Table1[[#This Row],[结束日期]] <= TODAY() ), "Completed", IF( OR( AND( Table1[[#This Row],[计划开始时间]] <= TODAY(), ISBLANK(Table1[[#This Row],[结束日期]]) ), AND( Table1[[#This Row],[计划开始时间]] <= TODAY(), Table1[[#This Row],[结束日期]] >= TODAY() ) ), "In Progress", "Not Started" ) ) ) )) -> In Progress | Z40: 46235 | AA40: =WORKDAY(Z40,Table1[[#This Row],[MD]]) -> 46276 | AB40: =Table1[[#This Row],[YR0 开发费用]] -> 9900 | AC40: 46232 | AF40: FY2627 Q1 | AH40: =IF(Table1[[#This Row],[Dev Pmt]]="",Table1[[#This Row],[YR0 开发费用]]-0,Table1[[#This Row],[YR0 开发费用]]-Table1[[#This Row],[Dev Pmt]]) -> 0
...

Sheet 2425财年需求时间安排
A1: 序号 | B1: 需求 | C1: 备注 | D1: 排序 | E1: MD | F1: 交付期限 | G1: 开始时间 | H1: 截止时间 | I1: 季度 | J1: USD | L1: 需求 | M1: 第一期划拨USD 9/27 | N1: Comment | O1: Difference | P1: 第二期划拨USD | Q1: Difference
A2: 2 | B2: 定期邮箱发送库存DB报告 | D2: 1 | E2: =VLOOKUP(B2,需求评估!$C:$L,10,0) -> 15 | F2: 2425 | G2: =VLOOKUP(B2,$B$15:$J$28,2,0) -> 45505 | H2: =VLOOKUP(B2,$B$15:$J$28,3,0) -> 45536 | I2: 2425 Q2 | J2: =SUMIFS(需求评估!$Q:$Q,需求评估!$C:$C,'2425财年需求时间安排'!$B2,需求评估!$M:$M,'2425财年需求时间安排'!$F2) -> 3780 | L2: 定期邮箱发送库存DB报告 | M2: 3780 | O2: =$J2-M2 -> 0 | Q2: =$J2-P2-M2 -> 0
A3: 4 | B3: 电池证书识别 V1 | D3: 2 | E3: =VLOOKUP(B3,需求评估!$C:$L,10,0) -> 15 | F3: 2425 | G3: =VLOOKUP(B3,$B$15:$J$28,2,0) -> 45537 | H3: =VLOOKUP(B3,$B$15:$J$28,3,0) -> 45565 | I3: 2425 Q2 | J3: =SUMIFS(需求评估!$Q:$Q,需求评估!$C:$C,'2425财年需求时间安排'!$B3,需求评估!$M:$M,'2425财年需求时间安排'!$F3) -> 3780 | L3: 电池证书识别 V1 | M3: 3780 | O3: =J3-M3 -> 0 | Q3: =$J3-P3-M3 -> 0
A4: 3 | B4: 电池主数据平台 V1 | C4: 第一期：权限管理（默认物流有权限、其他人需申请权限、super user）、数据查询、数据下载(PCG、TAB\MBG\ISG) | D4: 3 | E4: =VLOOKUP(B4,需求评估!$C:$L,10,0) -> 20 | F4: 2425 | G4: =VLOOKUP(B4,$B$15:$J$28,2,0) -> 45573 | H4: =VLOOKUP(B4,$B$15:$J$28,3,0) -> 45703 | I4: 2425 Q3 | J4: =SUMIFS(需求评估!$Q:$Q,需求评估!$C:$C,'2425财年需求时间安排'!$B4,需求评估!$M:$M,'2425财年需求时间安排'!$F4) -> 5040 | L4: 电池主数据平台 V1 | M4: 5040 | O4: =J4-M4 -> 0 | Q4: =$J4-P4-M4 -> 0
A5: 5 | B5: 电池供应商自动邮件 | D5: 4 | E5: =VLOOKUP(B5,需求评估!$C:$L,10,0) -> 5 | F5: 2526 | I5: 2526 Q1 | J5: =SUMIFS(需求评估!$Q:$Q,需求评估!$C:$C,'2425财年需求时间安排'!$B5,需求评估!$M:$M,'2425财年需求时间安排'!$F5) -> 1260 | L5: 电池供应商自动邮件 | M5: 1260 | N5: 项目延期,费用调整 | O5: =0-M5 -> -1260 | Q5: =0-P5-M5 -> -1260
A6: 6 | B6: 备件物流AI问答机器人 V1 | C6: teams收集信息，传给平台查询，再通过teams返回给用户物流状态及原因 第一期：集成teams AI实时查询物流状态， | D6: 5 | E6: =VLOOKUP(B6,需求评估!$C:$L,10,0) -> 70 | F6: 2425 | G6: =VLOOKUP(B6,$B$15:$J$28,2,0) -> 45621 | H6: =VLOOKUP(B6,$B$15:$J$28,3,0) -> 45808 | I6: 2425 Q3 | J6: =SUMIFS(需求评估!$Q:$Q,需求评估!$C:$C,'2425财年需求时间安排'!$B6,需求评估!$M:$M,'2425财年需求时间安排'!$F6) -> 51100 | L6: 备件物流AI问答机器人 V1 | M6: 7056 | O6: =J6-M6 -> 44044 | Q6: =$J6-P6-M6 -> 44044
A7: 7 | B7: AI对话搜集报价信息 | C7: 方案：设置物流teams hotline support 找teams team 合作：若用户引导用户输入物料尺寸、体积、重量、地址、是否含电池、是否有相应证书等，给Brian发邮件有新单据，Brian可以在平台上找到用户需求信息，评估价格，回复用户 | D7: 6 | E7: =VLOOKUP(B7,需求评估!$C:$L,10,0) -> #N/A | F7: 2425 | G7: =VLOOKUP(B7,$B$15:$J$28,2,0) -> 45705 | H7: =VLOOKUP(B7,$B$15:$J$28,3,0) -> 45729 | I7: 2425 Q4 | J7: =SUMIFS(需求评估!$Q:$Q,需求评估!$C:$C,'2425财年需求时间安排'!$B7,需求评估!$M:$M,'2425财年需求时间安排'!$F7) -> 0 | L7: AI对话搜集报价信息 | M7: 6048 | O7: =J7-M7 -> -6048 | Q7: =$J7-P7-M7 -> -6048
A8: 10 | B8: 发票信息自动抽取解析 V1 | C8: 第一期：部分平台已支持的语言OCR识别 | D8: 7 | E8: =VLOOKUP(B8,需求评估!$C:$L,10,0) -> 12 | F8: 2526 | G8: =VLOOKUP(B8,$B$15:$J$28,2,0) -> 45705 | H8: =VLOOKUP(B8,$B$15:$J$28,3,0) -> 45723 | I8: 2526 Q2 | J8: =SUMIFS(需求评估!$Q:$Q,需求评估!$C:$C,'2425财年需求时间安排'!$B8,需求评估!$M:$M,'2425财年需求时间安排'!$F8) -> 3024 | L8: 发票信息自动抽取解析 V1 | M8: 3024 | O8: =J8-M8 -> 0 | Q8: =$J8-P8-M8 -> 0
A9: 11 | B9: OA审批平台 | C9: 获取GAMS权限数据，审批过程的记录 业务：审批流和电子流 平台总需求：统一平台有权限审批的能力 | D9: 8 | E9: =VLOOKUP(B9,需求评估!$C:$L,10,0) -> 40 | F9: 2526 | G9: =VLOOKUP(B9,$B$15:$J$28,2,0) -> 45691 | H9: =VLOOKUP(B9,$B$15:$J$28,3,0) -> 45747 | I9: 2425 Q4 | J9: =SUMIFS(需求评估!$Q:$Q,需求评估!$C:$C,'2425财年需求时间安排'!$B9,需求评估!$M:$M,'2425财年需求时间安排'!$F9) -> 10080 | L9: OA审批平台 | M9: 10080 | O9: =J9-M9 -> 0 | Q9: =$J9-P9-M9 -> 0
A10: 12 | B10: SAP自动批量调库 | D10: 9 | E10: =VLOOKUP(B10,需求评估!$C:$L,10,0) -> 5 | F10: 2425 | G10: =VLOOKUP(B10,$B$15:$J$28,2,0) -> 45719 | H10: =VLOOKUP(B10,$B$15:$J$28,3,0) -> 45730 | I10: 2425 Q4 | J10: =SUMIFS(需求评估!$Q:$Q,需求评估!$C:$C,'2425财年需求时间安排'!$B10,需求评估!$M:$M,'2425财年需求时间安排'!$F10) -> 1260 | L10: SAP自动批量调库 | M10: 1260 | O10: =J10-M10 -> 0 | Q10: =$J10-P10-M10 -> 0
A11: 30 | B11: 干预模型 V1 | E11: =VLOOKUP(B11,需求评估!$C:$L,10,0) -> 40 | F11: 2425 | G11: =VLOOKUP(B11,$B$15:$J$28,2,0) -> 45541 | H11: =VLOOKUP(B11,$B$15:$J$28,3,0) -> 45625 | I11: 2425 Q3 | J11: =SUMIFS(需求评估!$Q:$Q,需求评估!$C:$C,'2425财年需求时间安排'!$B11,需求评估!$M:$M,'2425财年需求时间安排'!$F11) -> 15971.18 | L11: Rebalance 自动提取open订单 | M11: 1260 | N11: 额度可用 | O11: =J11-M11 -> 14711.18 | P11: 14711.18 | Q11: =$J11-P11-M11 -> 0
J12: =SUM(J2:J11)-J5 -> 94035.18 | M12: =SUM(M2:M11) -> 42588 | O12: =SUM(O2:O11) -> 51447.18 | P12: =SUM(P2:P11) -> 14711.18 | Q12: =SUM(Q2:Q11) -> 36736
Q14: =SUM(M12,Q12,P12) -> 94035.18 | R14: =J12-Q14 -> 0
A15: 序号 | B15: 需求名称 | C15: 计划进度 | F15: 实际进度 | N15: =SUM(M2:M11)+J11-需求评估!AB54 -> -279746 | O15: =M12+P12 -> 57299.18
C16: 开始日期 | D16: 结束日期 | E16: 计划工作日 | F16: 开始日期 | G16: 结束日期 | H16: 实际工作日 | J16: 完成状态
A17: 1 | B17: 定期邮箱发送库存DB报告 | C17: 45505 | D17: 45536 | E17: 22 | F17: =IFERROR(VLOOKUP($B17,需求评估!$C:$W,20,0),"") -> 45505 | G17: =IFERROR(VLOOKUP($B17,需求评估!$C:$W,21,0),"") -> 45545 | H17: 29 | J17: 已完成
A18: 2 | B18: 电池证书识别 V1 | C18: 45537 | D18: 45565 | E18: 21 | F18: =IFERROR(VLOOKUP($B18,需求评估!$C:$W,20,0),"") -> 45534 | G18: =IFERROR(VLOOKUP($B18,需求评估!$C:$W,21,0),"") -> 45595 | H18: 40 | J18: 已完成
A19: 3 | B19: 电池主数据平台 V1 | C19: 45573 | D19: 45703 | E19: 54 | F19: =IFERROR(VLOOKUP($B19,需求评估!$C:$W,20,0),"") -> 45581 | G19: =IFERROR(VLOOKUP($B19,需求评估!$C:$W,21,0),"") -> 45705 | H19: 84 | J19: 进行中
A20: 4 | B20: 电池供应商自动邮件 | C20: 45659 | D20: 45667 | E20: 12 | F20: =IFERROR(VLOOKUP($B20,需求评估!$C:$W,20,0),"") -> 45812 | G20: =IFERROR(VLOOKUP($B20,需求评估!$C:$W,21,0),"") -> 45905 | J20: 未启动
